Workbook
Name A: #REF!
Name A: #REF!
Name A: #REF!
Name A: #REF!
Name A: #REF!
Name Aa: #REF!
Name Aa: #REF!
Name Aa: #REF!
Name Aa: #REF!
Name Aa: #REF!
Name AB: [1]CG!$CA$9
Name Ad: [1]A.12!$AM$10
Name Ag: #REF!
Name alfa: [1]A.4!$AA$13
Name An: #REF!
Name Anchobloque: #REF!
Name As: [2]BALCONES!$N$32
Name Av: [1]A.2!$AC$11
Name bc_1: #REF!
Name bc_1: #REF!
Name bc_1: #REF!
Name bc_1: #REF!
Name bc_1: #REF!
Name bc_2: #REF!
Name bc_2: #REF!
Name bc_2: #REF!
Name bc_2: #REF!
Name bc_2: #REF!
Name bw: [2]ALIGERADA!$AD$20
Name bw: [2]ALIGERADA!$AD$20
Name bw: [2]ALIGERADA!$AD$20
Name bw: [2]ALIGERADA!$AD$20
Name bw: #REF!
Name Ct: [1]A.4!$U$13
Name Ctx: [1]CG!$BA$56
Name Cty: [1]CG!$BA$163
Name Cu: [1]A.4!$J$21
Name dp: [2]DX!$G$23
Name e: [2]ALIGERADA!$AM$37
Name e: [2]ALIGERADA!$AM$37
Name e: [2]ALIGERADA!$AM$37
Name e: [2]ALIGERADA!$AM$37
Name E: #REF!
Name E_Y1: [1]CG!$BR$55
Name E2X: [1]A.4!#REF!
Name E2Y: [1]A.4!#REF!
Name E3X: [1]A.4!#REF!
Name E3Y: [1]A.4!#REF!
Name E4X: [1]A.4!$AC$32
Name E4Y: [1]A.4!#REF!
Name E5X: [1]A.4!#REF!
Name E5Y: [1]A.4!#REF!
Name Ebloque: #REF!
Name ec: [2]DX!$G$29
Name Eestria: #REF!
Name Eestria: #REF!
Name Eestria: #REF!
Name Eestria: #REF!
Name Eestria: #REF!
Name Em: [1]INFO.!$BY$44

Sheet 0. HOJA BÁSICA
A1: JUAN JOSÉ ZAMORA JIMÉNEZ INGENIERO CIVIL | F1: Proyecto: | O1: Fecha:
O2: Diseño:
F3: Contiene: | O3: Revisión:

Sheet 0. PORTADA
B2: EDIFICACIÓN LOCALES COMERCIALES
B14: MIRANDA, VALLE DEL CAUCA
B16: MEMORIA DE CÁLCULOS ESTRUCTURALES
B60: MAYO DE 2025
B62: REVISIÓN 0

Sheet 0. CARTA RESPONSABILIDAD
A1: Memoria de cálculos estructurales | F1: Proyecto: | H1: ='0. PORTADA'!B2 -> EDIFICACIÓN LOCALES COMERCIALES | O1: Fecha: | Q1: Mayo de 2025
O2: Diseño:
F3: Contiene: | H3: Memorial de responsabilidad | O3: Revisión: | Q3: R0
B6: MEMORIAL DE RESPONSABILIDAD
B8: Santiago de Cali, Mayo de 2024
B10: Señor:
B11: *CLIENTE
B12: Santiago de Cali
B14: Cordial saludo,
B16: La presente tiene por objeto dar constancia que el diseño estructural de la edificación:
B17: ='0. PORTADA'!B2 -> EDIFICACIÓN LOCALES COMERCIALES
B18: ="El proyecto se encuenta ubicado en el municipio de "&'0. INICIO'!L9&" y fue realizado de acuerdo con el Reglamento Colombiano de Diseño y Construcción Sismo Resistente: NSR-10, "&"y demás disposiciones legales que rigen al respecto. Los estudios se ajustan en todo al mencionado reglamento, "&"en especial a lo concerniente al diseño sísmico, el cual se realizó para la zona de amenaza sísmica "&'0. INICIO'!L22&" dentro del cual se encuentra el proyecto." -> El proyecto se encuenta ubicado en el municipio de Miranda, Cauca y fue realizado de acuerdo con el Reglamento Colombiano de Diseño y Construcción Sismo Resistente: NSR-10, y demás disposiciones legales que rigen al respecto. Los estudios se ajustan en todo al mencionado reglamento, en especial a lo concerniente al diseño sísmico, el cual se realizó para la zona de amenaza sísmica ALTA dentro del cual se encuentra el proyecto.
B23: De acuerdo con lo indicado en el numeral A.9.3.1.1 del presente reglamento, recae sobre cada fabricante de elementos no estructurales la responsabilidad y diseño de estos, por lo que se es responsable únicamente de los aquí descritos en la memoria.
B26: Eximo a la ciudad de cualquier prejuicio que ocasione dicho cálculo estructural. Anexo fotocopia de la matricula profesional vigente y copia de las memorias de cálculo y los planos estructurales respectivos.
B29: Atentamente,
B46: JUAN JOSÉ ZAMORA JIMÉNEZ
B47: INGENIERO CIVIL/ESTRUCTURAL: JAVERIANA CALI
B48: MP. 171037-0527758 VLL

Sheet 0. INICIO
A1: ='0. CARTA RESPONSABILIDAD'!A1 -> Memoria de cálculos estructurales | F1: Proyecto: | H1: ='0. CARTA RESPONSABILIDAD'!H1 -> EDIFICACIÓN LOCALES COMERCIALES | O1: Fecha: | Q1: ='0. CARTA RESPONSABILIDAD'!Q1 -> Mayo de 2025
O2: Diseño: | Q2: ='0. CARTA RESPONSABILIDAD'!Q2 | W2: Tabla A.2.5-1
F3: Contiene: | H3: INFORMACIÓN GENERAL | O3: Revisión: | Q3: ='0. CARTA RESPONSABILIDAD'!Q3 -> R0 | W3: Grupo de Uso | X3: I
W4: I | X4: 1
B5: Proyecto | L5: LOCALES COMERCIALES | W5: II | X5: 1.1
W6: III | X6: 1.25
W7: IV | X7: 1.5
B9: Ubicación | L9: Miranda, Cauca
B10: Dirección
B11: Propietario
B12: Uso de la estructura | L12: Comercial
B13: Grupo de uso | L13: I
B14: Coeficiente de importancia (I) | L14: =VLOOKUP(L13,$W$4:$X$7,2,) -> 1
B15: Altura efectiva | L15: 8.1 | M15: m
B16: Sistema estructural de resistencia sísmica - Sentido Long. (A.3.2) | L16: Pórticos de concreto resistentes a momento
B17: Sistema estructural de resistencia sísmica - Sentido Transv. (A.3.2) | L17: Pórticos de concreto resistentes a momento
B18: Espectro de diseño | L18: NSR 10
B19: Tipo de Perfil de Suelo | L19: E | X19: 50 | Y19: =X19+Y20 -> 810
X20: 260 | Y20: =X20+Y21 -> 760
B21: Método de análisis sísmico (A.3.4) | L21: Modal | X21: 50 | Y21: =X21+Y22 -> 500
B22: Zona de amenaza sísmica (A.2.3) | L22: ALTA | X22: 450 | Y22: =X22+Y23 -> 450
B23: Capacidad de disipación de energía (A.3.1.3) | L23: {=_xlfn.IFS(L22="Baja","DMI",L22="Media","DMO",L22="Alta","DES")} -> DES
B24: Coef. de disipación de energía básico - Long.(A.3.1.3) | L24: Rox | M24: 7
B25: Coef. de disipación de energía básico - Transv.(A.3.1.3) | L25: Roy | M25: 7
B26: Coef. de aceleración pico efectiva (A.2.3.2) | L26: Aa | M26: 0.25
B27: Coef. de velocidad pico efectiva (A.2.3.3) | L27: Av | M27: 0.2
B28: Coef. de Importancia (A.2.5.2) | L28: I | M28: =L14 -> 1
B29: Coef. de amplificación de la aceleración (periodos cortos) | L29: Fa | M29: ='3. ESPECTRO'!M23 -> 1.45
B30: Coef. de amplificación de la aceleración (periodos intermedios) | L30: Fv | M30: ='3. ESPECTRO'!M24 -> 3.2 | N30: ='3. ESPECTRO'!AH76
B31: Coef. de reducción de Ro por irregularidad en Planta (A.3.3.4) | L31: φp | M31: ='5. IRREGULARIDADES'!M147 -> 1 | N31: ='3. ESPECTRO'!AH77
B32: Coef. de reducción de Ro por irregularidad en Altura (A.3.3.4) | L32: φa | M32: ='5. IRREGULARIDADES'!M146 -> 1
B33: Coef. de reducción de Ro por ausencia de redundancia (A.3.3.8) | L33: φr x | M33: ='5. IRREGULARIDADES'!M148 -> 0.75
B34: Coef. de reducción de Ro por ausencia de redundancia (A.3.3.8) | L34: φr y | M34: ='5. IRREGULARIDADES'!I140 -> 1
B35: Coef. de capacidad de disipación de energía - Sentido X (A.3) | L35: Rx | M35: ='5. IRREGULARIDADES'!M150 -> 5.25
B36: Coef. de capacidad de disipación de energía - Sentido Y (A.3) | L36: Ry | M36: ='5. IRREGULARIDADES'!P150 -> 7
B37: Periodo de vibración fundamental aproximado (A.4.2) | L37: Ta | M37: ='7. FHE Y AJUSTE DE SISMO'!P12 -> 0.30884059
B38: Periodo obtenido del análisis dinámico en la dirección X | L38: Tx | M38: ='7. FHE Y AJUSTE DE SISMO'!H16 -> 0.375
B39: Periodo obtenido del análisis dinámico en la dirección Y | L39: Ty | M39: ='7. FHE Y AJUSTE DE SISMO'!H17 -> 0.429
B40: Factor de corrección en la dirección X (A.5.5.4) | L40: FC1 | M40: ='7. FHE Y AJUSTE DE SISMO'!P51 -> 1
B41: Factor de corrección en la dirección Y (A.5.5.4) | L41: FC2 | M41: ='7. FHE Y AJUSTE DE SISMO'!P52 -> 1
...

Sheet 1. AVALÚO DE CARGAS
A1: ='0. CARTA RESPONSABILIDAD'!A1 -> Memoria de cálculos estructurales | F1: Proyecto: | H1: ='0. CARTA RESPONSABILIDAD'!H1 -> EDIFICACIÓN LOCALES COMERCIALES | O1: Fecha: | Q1: ='0. CARTA RESPONSABILIDAD'!Q1 -> Mayo de 2025
O2: Diseño: | Q2: ='0. CARTA RESPONSABILIDAD'!Q2
F3: Contiene: | H3: DEFINICIÓN DE CARGAS | O3: Revisión: | Q3: ='0. CARTA RESPONSABILIDAD'!Q3 -> R0
B5: 1. DEFINICIÓN DE CARGAS
B8: 1.1 Cargas muertas
B10: Las cargas muertas consideradas para el diseño de la estructura son debidas al sistema de red contraincendios, redes eléctricas, hidráulicas y sanitarias, elementos menores, entre otros. El peso propio de los elementos estructurales es considerado automáticamente por el software de diseño estructural.
C14: Cargas muertas - peso propio entrepiso
D15: t total | H15: 45 | I15: cm | K15: Espesor losa | W15: Cargas de entrepiso
D16: t loseta sup. | H16: 5 | I16: cm | K16: Espesor loseta superior | W16: Acabados h=5cm | AC16: =2400*0.05 -> 120 | AD16: Kg/m2 = | AF16: =AC16*10/1000 -> 1.2 | AG16: KN/m2
D17: t loseta inf. | H17: 0 | I17: cm | K17: Espesor loseta inferior | W17: Instalaciones | AC17: 5 | AD17: Kg/m2 = | AF17: =AC17*10/1000 -> 0.05 | AG17: KN/m2
D18: S viguetas | H18: 120 | I18: cm | K18: Separación viguetas | W18: Muros y divisiones | AC18: 180 | AD18: Kg/m2 = | AF18: =AC18*10/1000 -> 1.8 | AG18: KN/m2
D19: b viguetas | H19: 12 | I19: cm | K19: Ancho viguetas
D20: S riostras | H20: 337.5 | I20: cm | K20: Separación riostras | W20: Total | AC20: =SUM(AC16:AC18) -> 305 | AD20: Kg/m2 = | AF20: =AC20*10/1000 -> 3.05 | AG20: KN/m2
D21: b riostras | H21: 10 | I21: cm | K21: Ancho riostras
D22: Peso Loseta superior | H22: =H16*2400/100 -> 120 | I22: Kg/m2 = | K22: =H22*10/1000 -> 1.2 | L22: KN/m2
D23: Peso Loseta inferior | H23: =H17*2400/100 -> 0 | I23: Kg/m2 = | K23: =H23*10/1000 -> 0 | L23: KN/m2
D24: Peso viguetas | H24: =(H15-H16-H17)/100*(H19/100)*2400*100/(H18) -> 96 | I24: Kg/m2 = | K24: =H24*10/1000 -> 0.96 | L24: KN/m2
D25: Peso viguetas | H25: =IF(H20=0,0,(H15-H16-H17)/100*(H21/100)*2400*100/(H20)) -> 28.444444 | I25: Kg/m2 = | K25: =H25*10/1000 -> 0.28444444 | L25: KN/m2
D27: Peso propio total losa | H27: =SUM(H22:H25) -> 244.44444 | I27: Kg/m2 = | K27: =H27*10/1000 -> 2.4444444 | L27: KN/m2
C29: Cargas muertas - sobreimpuestas | AK29: Interpolación
D30: Acabados h=5cm | H30: =2400*0.05 -> 120 | I30: Kg/m2 = | K30: =H30*10/1000 -> 1.2 | L30: KN/m2
D31: Instalaciones | H31: 50 | I31: Kg/m2 = | K31: =H31*10/1000 -> 0.5 | L31: KN/m2 | AK31: Espesor | AM31: 10 | AN31: 12 | AO31: 15
D32: Muros y divisiones | H32: 0 | I32: Kg/m2 = | K32: =H32*10/1000 -> 0 | L32: KN/m2 | AM32: 180 | AN32: =AO32-(AO32-AM32)*(AO31-AN31)/(AO31-AM31) -> 208 | AO32: 250
D33: Cielo falso | H33: 10 | I33: Kg/m2 = | K33: =H33*10/1000 -> 0.1 | L33: KN/m2
D35: Total | H35: =SUM(H30:H33) -> 180 | I35: Kg/m2 = | K35: =SUM(K30:K33) -> 1.8 | L35: KN/m2
C37: Cargas muertas - fachadas
D38: Muros de fachada | H38: 180 | I38: Kg/m2 = | K38: =H38*10/1000 -> 1.8 | L38: KN/m2
D39: Altura promedio | H39: 2.6 | I39: m
D40: Carga lineal | H40: =+H38*H39 -> 468 | I40: Kg/m = | K40: =H40*10/1000 -> 4.68 | L40: KN/m
D42: Mampostería de bloque de arcilla, de espesor 10cm, pañetado en ambas caras.
AT43: Muros de antepecho | AX43: 208 | AY43: Kg/m2 = | BA43: =AX43*10/1000 -> 2.08 | BB43: KN/m2
AT44: Altura promedio | AX44: 1.2 | AY44: m
B45: 1.2 Cargas vivas | AH45: Cargas muertas - cubierta | AT45: Carga lineal | AX45: =+AX43*AX44 -> 249.6 | AY45: Kg/m = | BA45: =AX45*10/1000 -> 2.496 | BB45: KN/m
W46: Cargas muertas - cubierta | AI46: Teja | AM46: 15 | AN46: Kg/m2 = | AP46: =AM46*10/1000 -> 0.15 | AQ46: KN/m2
B47: Según la Tabla B.4.2.1-1 de la NSR-10, se deben considerar cargas uniformemente repartidas en la estructura debida al uso, las cuales se definen en magnitud según el tipo de ocupación del edificio o área de entrepiso. Por lo tanto, para los diferentes niveles y ocupaciones del proyecto se presentan las siguientes cargas vivas implementadas: | X47: Teja | AB47: 0 | AC47: Kg/m2 = | AE47: =AB47*10/1000 -> 0 | AF47: KN/m2 | AI47: Instalaciones | AM47: 5 | AN47: Kg/m2 = | AP47: =AM47*10/1000 -> 0.05 | AQ47: KN/m2
X48: Instalaciones | AB48: 0 | AC48: Kg/m2 = | AE48: =AB48*10/1000 -> 0 | AF48: KN/m2 | AI48: Total | AM48: =SUM(AM46:AM47) -> 20 | AN48: Kg/m2 = | AP48: =AM48*10/1000 -> 0.2 | AQ48: KN/m2
B51: Carga viva entrepiso - zona de locales* | H51: 350 | I51: Kg/m2 = | K51: =H51*10/1000 -> 3.5 | L51: KN/m2 | N51: A petición del cliente.
B52: Carga viva cubierta inclinación <15° | H52: 50 | I52: Kg/m2 = | K52: =H52*10/1000 -> 0.5 | L52: KN/m2 | AL52: 21.75
AL53: 12.1
AL54: 7.1
...

Sheet 2. CONFIGURACIÓN
A1: ='0. CARTA RESPONSABILIDAD'!A1 -> Memoria de cálculos estructurales | F1: Proyecto: | H1: ='0. CARTA RESPONSABILIDAD'!H1 -> EDIFICACIÓN LOCALES COMERCIALES | O1: Fecha: | Q1: ='0. CARTA RESPONSABILIDAD'!Q1 -> Mayo de 2025
O2: Diseño: | Q2: ='0. CARTA RESPONSABILIDAD'!Q2
F3: Contiene: | H3: CONFIGURACIÓN DE LA ESTRUCTURA | O3: Revisión: | Q3: ='0. CARTA RESPONSABILIDAD'!Q3 -> R0
B5: 2. CONFIGURACIÓN
B49: Planta nivel N+5.00
B107: Planta nivel N+8.10
B150: Elevación eje A y C
B172: Elevación eje B

Sheet 3. ESPECTRO
A1: ='0. CARTA RESPONSABILIDAD'!A1 -> Memoria de cálculos estructurales | F1: Proyecto: | H1: ='0. CARTA RESPONSABILIDAD'!H1 -> EDIFICACIÓN LOCALES COMERCIALES | O1: Fecha: | Q1: ='0. CARTA RESPONSABILIDAD'!Q1 -> Mayo de 2025 | AP1: ESPECTRO NSR10 | AT1: ESPECTRO MZSC | AZ1: Escogido | BA1: =IF(F16="NSR 10",AP1,AT1) -> ESPECTRO NSR10
O2: Diseño: | Q2: ='0. CARTA RESPONSABILIDAD'!Q2 | W2: 1 | X2: 2 | Y2: 3 | Z2: 4 | AA2: 5 | AB2: 6 | AC2: 7 | AD2: 8 | AE2: 9 | AF2: 10 | AG2: 11 | AH2: 12 | AI2: 13 | AL2: NSR 10 | AP2: T | AQ2: Sa | AT2: T | AU2: Sa1 | AV2: Sa2 | AW2: Sa | AZ2: T | BA2: Sa
F3: Contiene: | H3: PARÁMETROS SÍSMICOS | O3: Revisión: | Q3: ='0. CARTA RESPONSABILIDAD'!Q3 -> R0 | AL3: Tc | AM3: =0.48*M21*M24/(M20*M23) -> 0.84744828 | AP3: 0 | AQ3: =IF(AP3<$AM$3,2.5*$M$20*$M$23,IF(AND(AP3>=$AM$3,AP3<$AM$4),1.2*$M$21*$M$24/AP3,1.2*$M$21*$M$24*$AM$4/AP3^2)) -> 0.90625 | AT3: 0 | AU3: =IF(AT3<$AM$8,2.5*$M$20*$M$23*$F$18,IF(AND(AT3>=$AM$8,AT3<$AM$9),1.2*$M$21*$M$24*$F$18/AT3,1.2*$M$21*$M$24*$AM$9*$F$18/AT3^2)) -> #N/A | AV3: =IF(AT3<$AN$8,2.5*$M$20*$AH$76*$F$18,IF(AND(AT3>=$AN$8,AT3<$AN$9),1.2*$M$21*$AH$77*$F$18/AT3,1.2*$M$21*$AH$77*$AN$9*$F$18/AT3^2)) -> #N/A | AW3: =MAX(AU3:AV3) -> #N/A | AZ3: 0 | BA3: =IF($F$16="NSR 10",AQ3,AW3) -> 0.90625
W4: Fa - Tabla A.2.4-3 | AL4: TL | AM4: =2.4*M24 -> 7.68 | AP4: =AP3+0.05 -> 0.05 | AQ4: =IF(AP4<$AM$3,2.5*$M$20*$M$23,IF(AND(AP4>=$AM$3,AP4<$AM$4),1.2*$M$21*$M$24/AP4,1.2*$M$21*$M$24*$AM$4/AP4^2)) -> 0.90625 | AT4: =AT3+0.05 -> 0.05 | AU4: =IF(AT4<$AM$8,2.5*$M$20*$M$23*$F$18,IF(AND(AT4>=$AM$8,AT4<$AM$9),1.2*$M$21*$M$24*$F$18/AT4,1.2*$M$21*$M$24*$AM$9*$F$18/AT4^2)) -> #N/A | AV4: =IF(AT4<$AN$8,2.5*$M$20*$AH$76*$F$18,IF(AND(AT4>=$AN$8,AT4<$AN$9),1.2*$M$21*$AH$77*$F$18/AT4,1.2*$M$21*$AH$77*$AN$9*$F$18/AT4^2)) -> #N/A | AW4: =MAX(AU4:AV4) -> #N/A | AZ4: =AZ3+0.05 -> 0.05 | BA4: =IF($F$16="NSR 10",AQ4,AW4) -> 0.90625
B5: 3. PARÁMETROS SÍSMICOS | W5: Perfil de suelo | X5: Aa | AI5: Aa | AP5: =AP4+0.05 -> 0.1 | AQ5: =IF(AP5<$AM$3,2.5*$M$20*$M$23,IF(AND(AP5>=$AM$3,AP5<$AM$4),1.2*$M$21*$M$24/AP5,1.2*$M$21*$M$24*$AM$4/AP5^2)) -> 0.90625 | AT5: =AT4+0.05 -> 0.1 | AU5: =IF(AT5<$AM$8,2.5*$M$20*$M$23*$F$18,IF(AND(AT5>=$AM$8,AT5<$AM$9),1.2*$M$21*$M$24*$F$18/AT5,1.2*$M$21*$M$24*$AM$9*$F$18/AT5^2)) -> #N/A | AV5: =IF(AT5<$AN$8,2.5*$M$20*$AH$76*$F$18,IF(AND(AT5>=$AN$8,AT5<$AN$9),1.2*$M$21*$AH$77*$F$18/AT5,1.2*$M$21*$AH$77*$AN$9*$F$18/AT5^2)) -> #N/A | AW5: =MAX(AU5:AV5) -> #N/A | AZ5: =AZ4+0.05 -> 0.1 | BA5: =IF($F$16="NSR 10",AQ5,AW5) -> 0.90625
X6: 0.05 | Y6: =+X6+0.05 -> 0.1 | Z6: =+Y6+0.05 -> 0.15 | AA6: =+Z6+0.05 -> 0.2 | AB6: =+AA6+0.05 -> 0.25 | AC6: =+AB6+0.05 -> 0.3 | AD6: =+AC6+0.05 -> 0.35 | AE6: =+AD6+0.05 -> 0.4 | AF6: =+AE6+0.05 -> 0.45 | AG6: =+AF6+0.05 -> 0.5 | AI6: =M20 -> 0.25 | AL6: MZSC | AP6: =AP5+0.05 -> 0.15 | AQ6: =IF(AP6<$AM$3,2.5*$M$20*$M$23,IF(AND(AP6>=$AM$3,AP6<$AM$4),1.2*$M$21*$M$24/AP6,1.2*$M$21*$M$24*$AM$4/AP6^2)) -> 0.90625 | AT6: =AT5+0.05 -> 0.15 | AU6: =IF(AT6<$AM$8,2.5*$M$20*$M$23*$F$18,IF(AND(AT6>=$AM$8,AT6<$AM$9),1.2*$M$21*$M$24*$F$18/AT6,1.2*$M$21*$M$24*$AM$9*$F$18/AT6^2)) -> #N/A | AV6: =IF(AT6<$AN$8,2.5*$M$20*$AH$76*$F$18,IF(AND(AT6>=$AN$8,AT6<$AN$9),1.2*$M$21*$AH$77*$F$18/AT6,1.2*$M$21*$AH$77*$AN$9*$F$18/AT6^2)) -> #N/A | AW6: =MAX(AU6:AV6) -> #N/A | AZ6: =AZ5+0.05 -> 0.15 | BA6: =IF($F$16="NSR 10",AQ6,AW6) -> 0.90625
W7: A | X7: 0.8 | Y7: 0.8 | Z7: =AVERAGE(Y7,AA7) -> 0.8 | AA7: 0.8 | AB7: =AVERAGE(AA7,AC7) -> 0.8 | AC7: 0.8 | AD7: =AVERAGE(AC7,AE7) -> 0.8 | AE7: 0.8 | AF7: =AVERAGE(AE7,AG7) -> 0.8 | AG7: 0.8 | AI7: =HLOOKUP(AI$6,$X6:$AG7,2,) -> 0.8 | AM7: 1 | AN7: 2 | AP7: =AP6+0.05 -> 0.2 | AQ7: =IF(AP7<$AM$3,2.5*$M$20*$M$23,IF(AND(AP7>=$AM$3,AP7<$AM$4),1.2*$M$21*$M$24/AP7,1.2*$M$21*$M$24*$AM$4/AP7^2)) -> 0.90625 | AT7: =AT6+0.05 -> 0.2 | AU7: =IF(AT7<$AM$8,2.5*$M$20*$M$23*$F$18,IF(AND(AT7>=$AM$8,AT7<$AM$9),1.2*$M$21*$M$24*$F$18/AT7,1.2*$M$21*$M$24*$AM$9*$F$18/AT7^2)) -> #N/A | AV7: =IF(AT7<$AN$8,2.5*$M$20*$AH$76*$F$18,IF(AND(AT7>=$AN$8,AT7<$AN$9),1.2*$M$21*$AH$77*$F$18/AT7,1.2*$M$21*$AH$77*$AN$9*$F$18/AT7^2)) -> #N/A | AW7: =MAX(AU7:AV7) -> #N/A | AZ7: =AZ6+0.05 -> 0.2 | BA7: =IF($F$16="NSR 10",AQ7,AW7) -> 0.90625
B8: ="Para la evaluación de la carga sísmica en la bodega se tiene en cuenta que el proyecto se encuentra ubicado en el municipio de "&'0. INICIO'!L9&", el cual, según el apéndice A-4 (Valores de Aa, Av, Ae y Ad y definición de la zona de amenaza sísmica de los municipios colombianos), se presenta como una zona de amenaza sísmica "&'0. INICIO'!L22&". Así mismo, teniendo en cuenta la información suministrada en el informe geotécnico, se obtienen los coeficientes necesarios para considerar los fectos de sitio (Aa y Av)." -> Para la evaluación de la carga sísmica en la bodega se tiene en cuenta que el proyecto se encuentra ubicado en el municipio de Miranda, Cauca, el cual, según el apéndice A-4 (Valores de Aa, Av, Ae y Ad y definición de la zona de amenaza sísmica de los municipios colombianos), se presenta como una zona de amenaza sísmica ALTA. Así mismo, teniendo en cuenta la información suministrada en el informe geotécnico, se obtienen los coeficientes necesarios para considerar los fectos de sitio (Aa y Av). | W8: B | X8: 1 | Y8: 1 | Z8: =AVERAGE(Y8,AA8) -> 1 | AA8: 1 | AB8: =AVERAGE(AA8,AC8) -> 1 | AC8: 1 | AD8: =AVERAGE(AC8,AE8) -> 1 | AE8: 1 | AF8: =AVERAGE(AE8,AG8) -> 1 | AG8: 1 | AI8: =HLOOKUP(AI$6,$X6:$AG8,3,) -> 1 | AL8: Tc | AM8: =VLOOKUP($F$17,$W$25:$Y$34,3,) -> #N/A | AN8: =VLOOKUP($F$17,$W$39:$Y$48,3,) -> #N/A | AP8: =AP7+0.05 -> 0.25 | AQ8: =IF(AP8<$AM$3,2.5*$M$20*$M$23,IF(AND(AP8>=$AM$3,AP8<$AM$4),1.2*$M$21*$M$24/AP8,1.2*$M$21*$M$24*$AM$4/AP8^2)) -> 0.90625 | AT8: =AT7+0.05 -> 0.25 | AU8: =IF(AT8<$AM$8,2.5*$M$20*$M$23*$F$18,IF(AND(AT8>=$AM$8,AT8<$AM$9),1.2*$M$21*$M$24*$F$18/AT8,1.2*$M$21*$M$24*$AM$9*$F$18/AT8^2)) -> #N/A | AV8: =IF(AT8<$AN$8,2.5*$M$20*$AH$76*$F$18,IF(AND(AT8>=$AN$8,AT8<$AN$9),1.2*$M$21*$AH$77*$F$18/AT8,1.2*$M$21*$AH$77*$AN$9*$F$18/AT8^2)) -> #N/A | AW8: =MAX(AU8:AV8) -> #N/A | AZ8: =AZ7+0.05 -> 0.25 | BA8: =IF($F$16="NSR 10",AQ8,AW8) -> 0.90625
W9: C | X9: 1.2 | Y9: 1.2 | Z9: =AVERAGE(Y9,AA9) -> 1.2 | AA9: 1.2 | AB9: =AVERAGE(AA9,AC9) -> 1.15 | AC9: 1.1 | AD9: =AVERAGE(AC9,AE9) -> 1.05 | AE9: 1 | AF9: =AVERAGE(AE9,AG9) -> 1 | AG9: 1 | AI9: =HLOOKUP(AI$6,$X6:$AG9,4,) -> 1.15 | AL9: Tl | AM9: =VLOOKUP($F$17,$W$25:$AA$34,5,) -> #N/A | AN9: =VLOOKUP($F$17,$W$39:$AA$48,5,) -> #N/A | AP9: =AP8+0.05 -> 0.3 | AQ9: =IF(AP9<$AM$3,2.5*$M$20*$M$23,IF(AND(AP9>=$AM$3,AP9<$AM$4),1.2*$M$21*$M$24/AP9,1.2*$M$21*$M$24*$AM$4/AP9^2)) -> 0.90625 | AT9: =AT8+0.05 -> 0.3 | AU9: =IF(AT9<$AM$8,2.5*$M$20*$M$23*$F$18,IF(AND(AT9>=$AM$8,AT9<$AM$9),1.2*$M$21*$M$24*$F$18/AT9,1.2*$M$21*$M$24*$AM$9*$F$18/AT9^2)) -> #N/A | AV9: =IF(AT9<$AN$8,2.5*$M$20*$AH$76*$F$18,IF(AND(AT9>=$AN$8,AT9<$AN$9),1.2*$M$21*$AH$77*$F$18/AT9,1.2*$M$21*$AH$77*$AN$9*$F$18/AT9^2)) -> #N/A | AW9: =MAX(AU9:AV9) -> #N/A | AZ9: =AZ8+0.05 -> 0.3 | BA9: =IF($F$16="NSR 10",AQ9,AW9) -> 0.90625
W10: D | X10: 1.6 | Y10: 1.6 | Z10: =AVERAGE(Y10,AA10) -> 1.5 | AA10: 1.4 | AB10: =AVERAGE(AA10,AC10) -> 1.3 | AC10: 1.2 | AD10: =AVERAGE(AC10,AE10) -> 1.15 | AE10: 1.1 | AF10: =AVERAGE(AE10,AG10) -> 1.05 | AG10: 1 | AI10: =HLOOKUP(AI$6,$X6:$AG10,5,) -> 1.3 | AP10: =AP9+0.05 -> 0.35 | AQ10: =IF(AP10<$AM$3,2.5*$M$20*$M$23,IF(AND(AP10>=$AM$3,AP10<$AM$4),1.2*$M$21*$M$24/AP10,1.2*$M$21*$M$24*$AM$4/AP10^2)) -> 0.90625 | AT10: =AT9+0.05 -> 0.35 | AU10: =IF(AT10<$AM$8,2.5*$M$20*$M$23*$F$18,IF(AND(AT10>=$AM$8,AT10<$AM$9),1.2*$M$21*$M$24*$F$18/AT10,1.2*$M$21*$M$24*$AM$9*$F$18/AT10^2)) -> #N/A | AV10: =IF(AT10<$AN$8,2.5*$M$20*$AH$76*$F$18,IF(AND(AT10>=$AN$8,AT10<$AN$9),1.2*$M$21*$AH$77*$F$18/AT10,1.2*$M$21*$AH$77*$AN$9*$F$18/AT10^2)) -> #N/A | AW10: =MAX(AU10:AV10) -> #N/A | AZ10: =AZ9+0.05 -> 0.35 | BA10: =IF($F$16="NSR 10",AQ10,AW10) -> 0.90625
W11: E | X11: 2.5 | Y11: 2.5 | Z11: =AVERAGE(Y11,AA11) -> 2.1 | AA11: 1.7 | AB11: =AVERAGE(AA11,AC11) -> 1.45 | AC11: 1.2 | AD11: =AVERAGE(AC11,AE11) -> 1.05 | AE11: 0.9 | AF11: =AVERAGE(AE11,AG11) -> 0.9 | AG11: 0.9 | AI11: =HLOOKUP(AI$6,$X6:$AG11,6,) -> 1.45 | AP11: =AP10+0.05 -> 0.4 | AQ11: =IF(AP11<$AM$3,2.5*$M$20*$M$23,IF(AND(AP11>=$AM$3,AP11<$AM$4),1.2*$M$21*$M$24/AP11,1.2*$M$21*$M$24*$AM$4/AP11^2)) -> 0.90625 | AT11: =AT10+0.05 -> 0.4 | AU11: =IF(AT11<$AM$8,2.5*$M$20*$M$23*$F$18,IF(AND(AT11>=$AM$8,AT11<$AM$9),1.2*$M$21*$M$24*$F$18/AT11,1.2*$M$21*$M$24*$AM$9*$F$18/AT11^2)) -> #N/A | AV11: =IF(AT11<$AN$8,2.5*$M$20*$AH$76*$F$18,IF(AND(AT11>=$AN$8,AT11<$AN$9),1.2*$M$21*$AH$77*$F$18/AT11,1.2*$M$21*$AH$77*$AN$9*$F$18/AT11^2)) -> #N/A | AW11: =MAX(AU11:AV11) -> #N/A | AZ11: =AZ10+0.05 -> 0.4 | BA11: =IF($F$16="NSR 10",AQ11,AW11) -> 0.90625
AP12: =AP11+0.05 -> 0.45 | AQ12: =IF(AP12<$AM$3,2.5*$M$20*$M$23,IF(AND(AP12>=$AM$3,AP12<$AM$4),1.2*$M$21*$M$24/AP12,1.2*$M$21*$M$24*$AM$4/AP12^2)) -> 0.90625 | AT12: =AT11+0.05 -> 0.45 | AU12: =IF(AT12<$AM$8,2.5*$M$20*$M$23*$F$18,IF(AND(AT12>=$AM$8,AT12<$AM$9),1.2*$M$21*$M$24*$F$18/AT12,1.2*$M$21*$M$24*$AM$9*$F$18/AT12^2)) -> #N/A | AV12: =IF(AT12<$AN$8,2.5*$M$20*$AH$76*$F$18,IF(AND(AT12>=$AN$8,AT12<$AN$9),1.2*$M$21*$AH$77*$F$18/AT12,1.2*$M$21*$AH$77*$AN$9*$F$18/AT12^2)) -> #N/A | AW12: =MAX(AU12:AV12) -> #N/A | AZ12: =AZ11+0.05 -> 0.45 | BA12: =IF($F$16="NSR 10",AQ12,AW12) -> 0.90625
B13: Con base en los coeficientes asumidos anteriormente, se construye el espectro de diseño según A.2.6 de la NSR-10 para un coeficiente de amortiguamiento del 5% del amortiguamiento crítico expresado en función de la gravedad (g). | W13: Fv - Tabla A.2.4-4 | AP13: =AP12+0.05 -> 0.5 | AQ13: =IF(AP13<$AM$3,2.5*$M$20*$M$23,IF(AND(AP13>=$AM$3,AP13<$AM$4),1.2*$M$21*$M$24/AP13,1.2*$M$21*$M$24*$AM$4/AP13^2)) -> 0.90625 | AT13: =AT12+0.05 -> 0.5 | AU13: =IF(AT13<$AM$8,2.5*$M$20*$M$23*$F$18,IF(AND(AT13>=$AM$8,AT13<$AM$9),1.2*$M$21*$M$24*$F$18/AT13,1.2*$M$21*$M$24*$AM$9*$F$18/AT13^2)) -> #N/A | AV13: =IF(AT13<$AN$8,2.5*$M$20*$AH$76*$F$18,IF(AND(AT13>=$AN$8,AT13<$AN$9),1.2*$M$21*$AH$77*$F$18/AT13,1.2*$M$21*$AH$77*$AN$9*$F$18/AT13^2)) -> #N/A | AW13: =MAX(AU13:AV13) -> #N/A | AZ13: =AZ12+0.05 -> 0.5 | BA13: =IF($F$16="NSR 10",AQ13,AW13) -> 0.90625
W14: Perfil de suelo | X14: Av | AI14: Av | AP14: =AP13+0.05 -> 0.55 | AQ14: =IF(AP14<$AM$3,2.5*$M$20*$M$23,IF(AND(AP14>=$AM$3,AP14<$AM$4),1.2*$M$21*$M$24/AP14,1.2*$M$21*$M$24*$AM$4/AP14^2)) -> 0.90625 | AT14: =AT13+0.05 -> 0.55 | AU14: =IF(AT14<$AM$8,2.5*$M$20*$M$23*$F$18,IF(AND(AT14>=$AM$8,AT14<$AM$9),1.2*$M$21*$M$24*$F$18/AT14,1.2*$M$21*$M$24*$AM$9*$F$18/AT14^2)) -> #N/A | AV14: =IF(AT14<$AN$8,2.5*$M$20*$AH$76*$F$18,IF(AND(AT14>=$AN$8,AT14<$AN$9),1.2*$M$21*$AH$77*$F$18/AT14,1.2*$M$21*$AH$77*$AN$9*$F$18/AT14^2)) -> #N/A | AW14: =MAX(AU14:AV14) -> #N/A | AZ14: =AZ13+0.05 -> 0.55 | BA14: =IF($F$16="NSR 10",AQ14,AW14) -> 0.90625
X15: 0.05 | Y15: =+X15+0.05 -> 0.1 | Z15: =+Y15+0.05 -> 0.15 | AA15: =+Z15+0.05 -> 0.2 | AB15: =+AA15+0.05 -> 0.25 | AC15: =+AB15+0.05 -> 0.3 | AD15: =+AC15+0.05 -> 0.35 | AE15: =+AD15+0.05 -> 0.4 | AF15: =+AE15+0.05 -> 0.45 | AG15: =+AF15+0.05 -> 0.5 | AI15: =M21 -> 0.2 | AP15: =AP14+0.05 -> 0.6 | AQ15: =IF(AP15<$AM$3,2.5*$M$20*$M$23,IF(AND(AP15>=$AM$3,AP15<$AM$4),1.2*$M$21*$M$24/AP15,1.2*$M$21*$M$24*$AM$4/AP15^2)) -> 0.90625 | AT15: =AT14+0.05 -> 0.6 | AU15: =IF(AT15<$AM$8,2.5*$M$20*$M$23*$F$18,IF(AND(AT15>=$AM$8,AT15<$AM$9),1.2*$M$21*$M$24*$F$18/AT15,1.2*$M$21*$M$24*$AM$9*$F$18/AT15^2)) -> #N/A | AV15: =IF(AT15<$AN$8,2.5*$M$20*$AH$76*$F$18,IF(AND(AT15>=$AN$8,AT15<$AN$9),1.2*$M$21*$AH$77*$F$18/AT15,1.2*$M$21*$AH$77*$AN$9*$F$18/AT15^2)) -> #N/A | AW15: =MAX(AU15:AV15) -> #N/A | AZ15: =AZ14+0.05 -> 0.6 | BA15: =IF($F$16="NSR 10",AQ15,AW15) -> 0.90625
B16: ESPECTRO DE DISEÑO | F16: ='0. INICIO'!L18 -> NSR 10 | W16: A | Y16: 0.8 | Z16: =AVERAGE(Y16,AA16) -> 0.8 | AA16: 0.8 | AB16: =AVERAGE(AA16,AC16) -> 0.8 | AC16: 0.8 | AD16: =AVERAGE(AC16,AE16) -> 0.8 | AE16: 0.8 | AF16: =AVERAGE(AE16,AG16) -> 0.8 | AG16: 0.8 | AI16: =HLOOKUP(AI$15,$X15:$AG16,2,) -> 0.8 | AP16: =AP15+0.05 -> 0.65 | AQ16: =IF(AP16<$AM$3,2.5*$M$20*$M$23,IF(AND(AP16>=$AM$3,AP16<$AM$4),1.2*$M$21*$M$24/AP16,1.2*$M$21*$M$24*$AM$4/AP16^2)) -> 0.90625 | AT16: =AT15+0.05 -> 0.65 | AU16: =IF(AT16<$AM$8,2.5*$M$20*$M$23*$F$18,IF(AND(AT16>=$AM$8,AT16<$AM$9),1.2*$M$21*$M$24*$F$18/AT16,1.2*$M$21*$M$24*$AM$9*$F$18/AT16^2)) -> #N/A | AV16: =IF(AT16<$AN$8,2.5*$M$20*$AH$76*$F$18,IF(AND(AT16>=$AN$8,AT16<$AN$9),1.2*$M$21*$AH$77*$F$18/AT16,1.2*$M$21*$AH$77*$AN$9*$F$18/AT16^2)) -> #N/A | AW16: =MAX(AU16:AV16) -> #N/A | AZ16: =AZ15+0.05 -> 0.65 | BA16: =IF($F$16="NSR 10",AQ16,AW16) -> 0.90625
B17: Perfil de suelo | F17: ='0. INICIO'!L19 -> E | W17: B | Y17: 1 | Z17: =AVERAGE(Y17,AA17) -> 1 | AA17: 1 | AB17: =AVERAGE(AA17,AC17) -> 1 | AC17: 1 | AD17: =AVERAGE(AC17,AE17) -> 1 | AE17: 1 | AF17: =AVERAGE(AE17,AG17) -> 1 | AG17: 1 | AI17: =HLOOKUP(AI$15,$X15:$AG17,3,) -> 1 | AP17: =AP16+0.05 -> 0.7 | AQ17: =IF(AP17<$AM$3,2.5*$M$20*$M$23,IF(AND(AP17>=$AM$3,AP17<$AM$4),1.2*$M$21*$M$24/AP17,1.2*$M$21*$M$24*$AM$4/AP17^2)) -> 0.90625 | AT17: =AT16+0.05 -> 0.7 | AU17: =IF(AT17<$AM$8,2.5*$M$20*$M$23*$F$18,IF(AND(AT17>=$AM$8,AT17<$AM$9),1.2*$M$21*$M$24*$F$18/AT17,1.2*$M$21*$M$24*$AM$9*$F$18/AT17^2)) -> #N/A | AV17: =IF(AT17<$AN$8,2.5*$M$20*$AH$76*$F$18,IF(AND(AT17>=$AN$8,AT17<$AN$9),1.2*$M$21*$AH$77*$F$18/AT17,1.2*$M$21*$AH$77*$AN$9*$F$18/AT17^2)) -> #N/A | AW17: =MAX(AU17:AV17) -> #N/A | AZ17: =AZ16+0.05 -> 0.7 | BA17: =IF($F$16="NSR 10",AQ17,AW17) -> 0.90625
B18: Coeficiente de Importancia | F18: ='0. INICIO'!L14 -> 1 | W18: C | Y18: 1.7 | Z18: =AVERAGE(Y18,AA18) -> 1.65 | AA18: 1.6 | AB18: =AVERAGE(AA18,AC18) -> 1.55 | AC18: 1.5 | AD18: =AVERAGE(AC18,AE18) -> 1.45 | AE18: 1.4 | AF18: =AVERAGE(AE18,AG18) -> 1.35 | AG18: 1.3 | AI18: =HLOOKUP(AI$15,$X15:$AG18,4,) -> 1.6 | AP18: =AP17+0.05 -> 0.75 | AQ18: =IF(AP18<$AM$3,2.5*$M$20*$M$23,IF(AND(AP18>=$AM$3,AP18<$AM$4),1.2*$M$21*$M$24/AP18,1.2*$M$21*$M$24*$AM$4/AP18^2)) -> 0.90625 | AT18: =AT17+0.05 -> 0.75 | AU18: =IF(AT18<$AM$8,2.5*$M$20*$M$23*$F$18,IF(AND(AT18>=$AM$8,AT18<$AM$9),1.2*$M$21*$M$24*$F$18/AT18,1.2*$M$21*$M$24*$AM$9*$F$18/AT18^2)) -> #N/A | AV18: =IF(AT18<$AN$8,2.5*$M$20*$AH$76*$F$18,IF(AND(AT18>=$AN$8,AT18<$AN$9),1.2*$M$21*$AH$77*$F$18/AT18,1.2*$M$21*$AH$77*$AN$9*$F$18/AT18^2)) -> #N/A | AW18: =MAX(AU18:AV18) -> #N/A | AZ18: =AZ17+0.05 -> 0.75 | BA18: =IF($F$16="NSR 10",AQ18,AW18) -> 0.90625
W19: D | Y19: 2.4 | Z19: =AVERAGE(Y19,AA19) -> 2.2 | AA19: 2 | AB19: =AVERAGE(AA19,AC19) -> 1.9 | AC19: 1.8 | AD19: =AVERAGE(AC19,AE19) -> 1.7 | AE19: 1.6 | AF19: =AVERAGE(AE19,AG19) -> 1.55 | AG19: 1.5 | AI19: =HLOOKUP(AI$15,$X15:$AG19,5,) -> 2 | AP19: =AP18+0.05 -> 0.8 | AQ19: =IF(AP19<$AM$3,2.5*$M$20*$M$23,IF(AND(AP19>=$AM$3,AP19<$AM$4),1.2*$M$21*$M$24/AP19,1.2*$M$21*$M$24*$AM$4/AP19^2)) -> 0.90625 | AT19: =AT18+0.05 -> 0.8 | AU19: =IF(AT19<$AM$8,2.5*$M$20*$M$23*$F$18,IF(AND(AT19>=$AM$8,AT19<$AM$9),1.2*$M$21*$M$24*$F$18/AT19,1.2*$M$21*$M$24*$AM$9*$F$18/AT19^2)) -> #N/A | AV19: =IF(AT19<$AN$8,2.5*$M$20*$AH$76*$F$18,IF(AND(AT19>=$AN$8,AT19<$AN$9),1.2*$M$21*$AH$77*$F$18/AT19,1.2*$M$21*$AH$77*$AN$9*$F$18/AT19^2)) -> #N/A | AW19: =MAX(AU19:AV19) -> #N/A | AZ19: =AZ18+0.05 -> 0.8 | BA19: =IF($F$16="NSR 10",AQ19,AW19) -> 0.90625
B20: Coeficiente de aceleración pico efectiva | L20: Aa | M20: ='0. INICIO'!M26 -> 0.25 | W20: E | Y20: 3.5 | Z20: =AVERAGE(Y20,AA20) -> 3.35 | AA20: 3.2 | AB20: =AVERAGE(AA20,AC20) -> 3 | AC20: 2.8 | AD20: =AVERAGE(AC20,AE20) -> 2.6 | AE20: 2.4 | AF20: =AVERAGE(AE20,AG20) -> 2.4 | AG20: 2.4 | AI20: =HLOOKUP(AI$15,$X15:$AG20,6,) -> 3.2 | AP20: =AP19+0.05 -> 0.85 | AQ20: =IF(AP20<$AM$3,2.5*$M$20*$M$23,IF(AND(AP20>=$AM$3,AP20<$AM$4),1.2*$M$21*$M$24/AP20,1.2*$M$21*$M$24*$AM$4/AP20^2)) -> 0.90352941 | AT20: =AT19+0.05 -> 0.85 | AU20: =IF(AT20<$AM$8,2.5*$M$20*$M$23*$F$18,IF(AND(AT20>=$AM$8,AT20<$AM$9),1.2*$M$21*$M$24*$F$18/AT20,1.2*$M$21*$M$24*$AM$9*$F$18/AT20^2)) -> #N/A | AV20: =IF(AT20<$AN$8,2.5*$M$20*$AH$76*$F$18,IF(AND(AT20>=$AN$8,AT20<$AN$9),1.2*$M$21*$AH$77*$F$18/AT20,1.2*$M$21*$AH$77*$AN$9*$F$18/AT20^2)) -> #N/A | AW20: =MAX(AU20:AV20) -> #N/A | AZ20: =AZ19+0.05 -> 0.85 | BA20: =IF($F$16="NSR 10",AQ20,AW20) -> 0.90352941
B21: Coeficiente de velocidad pico efectiva | L21: Av | M21: ='0. INICIO'!M27 -> 0.2 | AP21: =AP20+0.05 -> 0.9 | AQ21: =IF(AP21<$AM$3,2.5*$M$20*$M$23,IF(AND(AP21>=$AM$3,AP21<$AM$4),1.2*$M$21*$M$24/AP21,1.2*$M$21*$M$24*$AM$4/AP21^2)) -> 0.85333333 | AT21: =AT20+0.05 -> 0.9 | AU21: =IF(AT21<$AM$8,2.5*$M$20*$M$23*$F$18,IF(AND(AT21>=$AM$8,AT21<$AM$9),1.2*$M$21*$M$24*$F$18/AT21,1.2*$M$21*$M$24*$AM$9*$F$18/AT21^2)) -> #N/A | AV21: =IF(AT21<$AN$8,2.5*$M$20*$AH$76*$F$18,IF(AND(AT21>=$AN$8,AT21<$AN$9),1.2*$M$21*$AH$77*$F$18/AT21,1.2*$M$21*$AH$77*$AN$9*$F$18/AT21^2)) -> #N/A | AW21: =MAX(AU21:AV21) -> #N/A | AZ21: =AZ20+0.05 -> 0.9 | BA21: =IF($F$16="NSR 10",AQ21,AW21) -> 0.85333333
B22: Coeficiente de Importancia (A.2.5.2) | L22: I | M22: ='0. INICIO'!M28 -> 1 | W22: ESPECTRO DE PERIODO CORTO | AF22: MZSC | AP22: =AP21+0.05 -> 0.95 | AQ22: =IF(AP22<$AM$3,2.5*$M$20*$M$23,IF(AND(AP22>=$AM$3,AP22<$AM$4),1.2*$M$21*$M$24/AP22,1.2*$M$21*$M$24*$AM$4/AP22^2)) -> 0.80842105 | AT22: =AT21+0.05 -> 0.95 | AU22: =IF(AT22<$AM$8,2.5*$M$20*$M$23*$F$18,IF(AND(AT22>=$AM$8,AT22<$AM$9),1.2*$M$21*$M$24*$F$18/AT22,1.2*$M$21*$M$24*$AM$9*$F$18/AT22^2)) -> #N/A | AV22: =IF(AT22<$AN$8,2.5*$M$20*$AH$76*$F$18,IF(AND(AT22>=$AN$8,AT22<$AN$9),1.2*$M$21*$AH$77*$F$18/AT22,1.2*$M$21*$AH$77*$AN$9*$F$18/AT22^2)) -> #N/A | AW22: =MAX(AU22:AV22) -> #N/A | AZ22: =AZ21+0.05 -> 0.95 | BA22: =IF($F$16="NSR 10",AQ22,AW22) -> 0.80842105
B23: Coeficiente de amplificación de la aceleración (periodos cortos) | L23: Fa | M23: =IF(F16="NSR 10",AE24,AF24) -> 1.45 | W23: Microzona | Y23: Aa | Z23: 0.25 | AA23: Av | AB23: 0.25 | AE23: NSR | AF23: Tcortos | AG23: Tlargos | AJ23: Fa | AK23: =IF(F16="NSR 10",AE24,AF24) -> 1.45 | AP23: =AP22+0.05 -> 1 | AQ23: =IF(AP23<$AM$3,2.5*$M$20*$M$23,IF(AND(AP23>=$AM$3,AP23<$AM$4),1.2*$M$21*$M$24/AP23,1.2*$M$21*$M$24*$AM$4/AP23^2)) -> 0.768 | AT23: =AT22+0.05 -> 1 | AU23: =IF(AT23<$AM$8,2.5*$M$20*$M$23*$F$18,IF(AND(AT23>=$AM$8,AT23<$AM$9),1.2*$M$21*$M$24*$F$18/AT23,1.2*$M$21*$M$24*$AM$9*$F$18/AT23^2)) -> #N/A | AV23: =IF(AT23<$AN$8,2.5*$M$20*$AH$76*$F$18,IF(AND(AT23>=$AN$8,AT23<$AN$9),1.2*$M$21*$AH$77*$F$18/AT23,1.2*$M$21*$AH$77*$AN$9*$F$18/AT23^2)) -> #N/A | AW23: =MAX(AU23:AV23) -> #N/A | AZ23: =AZ22+0.05 -> 1 | BA23: =IF($F$16="NSR 10",AQ23,AW23) -> 0.768
B24: Coeficiente de amplificación de la aceleración (periodos intermedios) | L24: Fv | M24: =IF(F16="NSR 10",AE25,AF25) -> 3.2 | Y24: Tc | Z24: Fa | AA24: TL | AB24: Fv | AD24: Fa | AE24: =VLOOKUP($F$17,W7:AI11,13,) -> 1.45 | AF24: =VLOOKUP($F$17,$W$25:$Z$34,4,) -> #N/A | AG24: =VLOOKUP($F$17,$W$39:$Z$48,4,) -> #N/A | AJ24: Fv | AK24: =IF(F16="NSR 10",AE25,AF25) -> 3.2 | AP24: =AP23+0.05 -> 1.05 | AQ24: =IF(AP24<$AM$3,2.5*$M$20*$M$23,IF(AND(AP24>=$AM$3,AP24<$AM$4),1.2*$M$21*$M$24/AP24,1.2*$M$21*$M$24*$AM$4/AP24^2)) -> 0.73142857 | AT24: =AT23+0.05 -> 1.05 | AU24: =IF(AT24<$AM$8,2.5*$M$20*$M$23*$F$18,IF(AND(AT24>=$AM$8,AT24<$AM$9),1.2*$M$21*$M$24*$F$18/AT24,1.2*$M$21*$M$24*$AM$9*$F$18/AT24^2)) -> #N/A | AV24: =IF(AT24<$AN$8,2.5*$M$20*$AH$76*$F$18,IF(AND(AT24>=$AN$8,AT24<$AN$9),1.2*$M$21*$AH$77*$F$18/AT24,1.2*$M$21*$AH$77*$AN$9*$F$18/AT24^2)) -> #N/A | AW24: =MAX(AU24:AV24) -> #N/A | AZ24: =AZ23+0.05 -> 1.05 | BA24: =IF($F$16="NSR 10",AQ24,AW24) -> 0.73142857
B25: Límite para periodos de vibración largos (A.2.6.1.2) | L25: Tc | M25: =IF(F16="NSR 10",AM3,AM8) -> 0.84744828 | W25: 1 | Y25: 0.55 | Z25: 0.86 | AA25: 3 | AB25: 0.99 | AD25: Fv | AE25: =VLOOKUP($F$17,W16:AI20,13,) -> 3.2 | AF25: =VLOOKUP($F$17,$W$25:$AB$34,6,) -> #N/A | AG25: =VLOOKUP($F$17,$W$39:$AB$48,6,) -> #N/A | AP25: =AP24+0.05 -> 1.1 | AQ25: =IF(AP25<$AM$3,2.5*$M$20*$M$23,IF(AND(AP25>=$AM$3,AP25<$AM$4),1.2*$M$21*$M$24/AP25,1.2*$M$21*$M$24*$AM$4/AP25^2)) -> 0.69818182 | AT25: =AT24+0.05 -> 1.1 | AU25: =IF(AT25<$AM$8,2.5*$M$20*$M$23*$F$18,IF(AND(AT25>=$AM$8,AT25<$AM$9),1.2*$M$21*$M$24*$F$18/AT25,1.2*$M$21*$M$24*$AM$9*$F$18/AT25^2)) -> #N/A | AV25: =IF(AT25<$AN$8,2.5*$M$20*$AH$76*$F$18,IF(AND(AT25>=$AN$8,AT25<$AN$9),1.2*$M$21*$AH$77*$F$18/AT25,1.2*$M$21*$AH$77*$AN$9*$F$18/AT25^2)) -> #N/A | AW25: =MAX(AU25:AV25) -> #N/A | AZ25: =AZ24+0.05 -> 1.1 | BA25: =IF($F$16="NSR 10",AQ25,AW25) -> 0.69818182
B26: Límite para periodos de vibración cortos (A.2.6.1.1) | L26: Tl | M26: =IF(F16="NSR 10",AM4,AM9) -> 7.68 | W26: 2 | Y26: 0.45 | Z26: 1.2 | AA26: 3 | AB26: 1.13 | AP26: =AP25+0.05 -> 1.15 | AQ26: =IF(AP26<$AM$3,2.5*$M$20*$M$23,IF(AND(AP26>=$AM$3,AP26<$AM$4),1.2*$M$21*$M$24/AP26,1.2*$M$21*$M$24*$AM$4/AP26^2)) -> 0.66782609 | AT26: =AT25+0.05 -> 1.15 | AU26: =IF(AT26<$AM$8,2.5*$M$20*$M$23*$F$18,IF(AND(AT26>=$AM$8,AT26<$AM$9),1.2*$M$21*$M$24*$F$18/AT26,1.2*$M$21*$M$24*$AM$9*$F$18/AT26^2)) -> #N/A | AV26: =IF(AT26<$AN$8,2.5*$M$20*$AH$76*$F$18,IF(AND(AT26>=$AN$8,AT26<$AN$9),1.2*$M$21*$AH$77*$F$18/AT26,1.2*$M$21*$AH$77*$AN$9*$F$18/AT26^2)) -> #N/A | AW26: =MAX(AU26:AV26) -> #N/A | AZ26: =AZ25+0.05 -> 1.15 | BA26: =IF($F$16="NSR 10",AQ26,AW26) -> 0.66782609
W27: 3 | Y27: 1.05 | Z27: 1.36 | AA27: 2 | AB27: 2.98 | AP27: =AP26+0.05 -> 1.2 | AQ27: =IF(AP27<$AM$3,2.5*$M$20*$M$23,IF(AND(AP27>=$AM$3,AP27<$AM$4),1.2*$M$21*$M$24/AP27,1.2*$M$21*$M$24*$AM$4/AP27^2)) -> 0.64 | AT27: =AT26+0.05 -> 1.2 | AU27: =IF(AT27<$AM$8,2.5*$M$20*$M$23*$F$18,IF(AND(AT27>=$AM$8,AT27<$AM$9),1.2*$M$21*$M$24*$F$18/AT27,1.2*$M$21*$M$24*$AM$9*$F$18/AT27^2)) -> #N/A | AV27: =IF(AT27<$AN$8,2.5*$M$20*$AH$76*$F$18,IF(AND(AT27>=$AN$8,AT27<$AN$9),1.2*$M$21*$AH$77*$F$18/AT27,1.2*$M$21*$AH$77*$AN$9*$F$18/AT27^2)) -> #N/A | AW27: =MAX(AU27:AV27) -> #N/A | AZ27: =AZ26+0.05 -> 1.2 | BA27: =IF($F$16="NSR 10",AQ27,AW27) -> 0.64
W28: 4a | Y28: 0.75 | Z28: 1.2 | AA28: 2 | AB28: 1.88 | AP28: =AP27+0.05 -> 1.25 | AQ28: =IF(AP28<$AM$3,2.5*$M$20*$M$23,IF(AND(AP28>=$AM$3,AP28<$AM$4),1.2*$M$21*$M$24/AP28,1.2*$M$21*$M$24*$AM$4/AP28^2)) -> 0.6144 | AT28: =AT27+0.05 -> 1.25 | AU28: =IF(AT28<$AM$8,2.5*$M$20*$M$23*$F$18,IF(AND(AT28>=$AM$8,AT28<$AM$9),1.2*$M$21*$M$24*$F$18/AT28,1.2*$M$21*$M$24*$AM$9*$F$18/AT28^2)) -> #N/A | AV28: =IF(AT28<$AN$8,2.5*$M$20*$AH$76*$F$18,IF(AND(AT28>=$AN$8,AT28<$AN$9),1.2*$M$21*$AH$77*$F$18/AT28,1.2*$M$21*$AH$77*$AN$9*$F$18/AT28^2)) -> #N/A | AW28: =MAX(AU28:AV28) -> #N/A | AZ28: =AZ27+0.05 -> 1.25 | BA28: =IF($F$16="NSR 10",AQ28,AW28) -> 0.6144
W29: 4b | X29: Tc | Y29: 0.7 | Z29: 1.04 | AA29: 2.5 | AB29: 1.52 | AP29: =AP28+0.05 -> 1.3 | AQ29: =IF(AP29<$AM$3,2.5*$M$20*$M$23,IF(AND(AP29>=$AM$3,AP29<$AM$4),1.2*$M$21*$M$24/AP29,1.2*$M$21*$M$24*$AM$4/AP29^2)) -> 0.59076923 | AT29: =AT28+0.05 -> 1.3 | AU29: =IF(AT29<$AM$8,2.5*$M$20*$M$23*$F$18,IF(AND(AT29>=$AM$8,AT29<$AM$9),1.2*$M$21*$M$24*$F$18/AT29,1.2*$M$21*$M$24*$AM$9*$F$18/AT29^2)) -> #N/A | AV29: =IF(AT29<$AN$8,2.5*$M$20*$AH$76*$F$18,IF(AND(AT29>=$AN$8,AT29<$AN$9),1.2*$M$21*$AH$77*$F$18/AT29,1.2*$M$21*$AH$77*$AN$9*$F$18/AT29^2)) -> #N/A | AW29: =MAX(AU29:AV29) -> #N/A | AZ29: =AZ28+0.05 -> 1.3 | BA29: =IF($F$16="NSR 10",AQ29,AW29) -> 0.59076923
W30: 4c | X30: Tc | Y30: 0.45 | Z30: 1.6 | AA30: 2 | AB30: 1.5 | AP30: =AP29+0.05 -> 1.35 | AQ30: =IF(AP30<$AM$3,2.5*$M$20*$M$23,IF(AND(AP30>=$AM$3,AP30<$AM$4),1.2*$M$21*$M$24/AP30,1.2*$M$21*$M$24*$AM$4/AP30^2)) -> 0.56888889 | AT30: =AT29+0.05 -> 1.35 | AU30: =IF(AT30<$AM$8,2.5*$M$20*$M$23*$F$18,IF(AND(AT30>=$AM$8,AT30<$AM$9),1.2*$M$21*$M$24*$F$18/AT30,1.2*$M$21*$M$24*$AM$9*$F$18/AT30^2)) -> #N/A | AV30: =IF(AT30<$AN$8,2.5*$M$20*$AH$76*$F$18,IF(AND(AT30>=$AN$8,AT30<$AN$9),1.2*$M$21*$AH$77*$F$18/AT30,1.2*$M$21*$AH$77*$AN$9*$F$18/AT30^2)) -> #N/A | AW30: =MAX(AU30:AV30) -> #N/A | AZ30: =AZ29+0.05 -> 1.35 | BA30: =IF($F$16="NSR 10",AQ30,AW30) -> 0.56888889
W31: 4d | Y31: 1.2 | Z31: 0.99 | AA31: 2 | AB31: 2.48 | AP31: =AP30+0.05 -> 1.4 | AQ31: =IF(AP31<$AM$3,2.5*$M$20*$M$23,IF(AND(AP31>=$AM$3,AP31<$AM$4),1.2*$M$21*$M$24/AP31,1.2*$M$21*$M$24*$AM$4/AP31^2)) -> 0.54857143 | AT31: =AT30+0.05 -> 1.4 | AU31: =IF(AT31<$AM$8,2.5*$M$20*$M$23*$F$18,IF(AND(AT31>=$AM$8,AT31<$AM$9),1.2*$M$21*$M$24*$F$18/AT31,1.2*$M$21*$M$24*$AM$9*$F$18/AT31^2)) -> #N/A | AV31: =IF(AT31<$AN$8,2.5*$M$20*$AH$76*$F$18,IF(AND(AT31>=$AN$8,AT31<$AN$9),1.2*$M$21*$AH$77*$F$18/AT31,1.2*$M$21*$AH$77*$AN$9*$F$18/AT31^2)) -> #N/A | AW31: =MAX(AU31:AV31) -> #N/A | AZ31: =AZ30+0.05 -> 1.4 | BA31: =IF($F$16="NSR 10",AQ31,AW31) -> 0.54857143
W32: 4e | Y32: 0.95 | Z32: 0.91 | AA32: 3 | AB32: 1.81 | AP32: =AP31+0.05 -> 1.45 | AQ32: =IF(AP32<$AM$3,2.5*$M$20*$M$23,IF(AND(AP32>=$AM$3,AP32<$AM$4),1.2*$M$21*$M$24/AP32,1.2*$M$21*$M$24*$AM$4/AP32^2)) -> 0.52965517 | AT32: =AT31+0.05 -> 1.45 | AU32: =IF(AT32<$AM$8,2.5*$M$20*$M$23*$F$18,IF(AND(AT32>=$AM$8,AT32<$AM$9),1.2*$M$21*$M$24*$F$18/AT32,1.2*$M$21*$M$24*$AM$9*$F$18/AT32^2)) -> #N/A | AV32: =IF(AT32<$AN$8,2.5*$M$20*$AH$76*$F$18,IF(AND(AT32>=$AN$8,AT32<$AN$9),1.2*$M$21*$AH$77*$F$18/AT32,1.2*$M$21*$AH$77*$AN$9*$F$18/AT32^2)) -> #N/A | AW32: =MAX(AU32:AV32) -> #N/A | AZ32: =AZ31+0.05 -> 1.45 | BA32: =IF($F$16="NSR 10",AQ32,AW32) -> 0.52965517
W33: 5 | X33: Tc | Y33: 0.6 | Z33: 1.12 | AA33: 2.5 | AB33: 1.4 | AP33: =AP32+0.05 -> 1.5 | AQ33: =IF(AP33<$AM$3,2.5*$M$20*$M$23,IF(AND(AP33>=$AM$3,AP33<$AM$4),1.2*$M$21*$M$24/AP33,1.2*$M$21*$M$24*$AM$4/AP33^2)) -> 0.512 | AT33: =AT32+0.05 -> 1.5 | AU33: =IF(AT33<$AM$8,2.5*$M$20*$M$23*$F$18,IF(AND(AT33>=$AM$8,AT33<$AM$9),1.2*$M$21*$M$24*$F$18/AT33,1.2*$M$21*$M$24*$AM$9*$F$18/AT33^2)) -> #N/A | AV33: =IF(AT33<$AN$8,2.5*$M$20*$AH$76*$F$18,IF(AND(AT33>=$AN$8,AT33<$AN$9),1.2*$M$21*$AH$77*$F$18/AT33,1.2*$M$21*$AH$77*$AN$9*$F$18/AT33^2)) -> #N/A | AW33: =MAX(AU33:AV33) -> #N/A | AZ33: =AZ32+0.05 -> 1.5 | BA33: =IF($F$16="NSR 10",AQ33,AW33) -> 0.512
W34: 6 | Y34: 1.15 | Z34: 1.09 | AA34: 2.5 | AB34: 2.61 | AP34: =AP33+0.05 -> 1.55 | AQ34: =IF(AP34<$AM$3,2.5*$M$20*$M$23,IF(AND(AP34>=$AM$3,AP34<$AM$4),1.2*$M$21*$M$24/AP34,1.2*$M$21*$M$24*$AM$4/AP34^2)) -> 0.49548387 | AT34: =AT33+0.05 -> 1.55 | AU34: =IF(AT34<$AM$8,2.5*$M$20*$M$23*$F$18,IF(AND(AT34>=$AM$8,AT34<$AM$9),1.2*$M$21*$M$24*$F$18/AT34,1.2*$M$21*$M$24*$AM$9*$F$18/AT34^2)) -> #N/A | AV34: =IF(AT34<$AN$8,2.5*$M$20*$AH$76*$F$18,IF(AND(AT34>=$AN$8,AT34<$AN$9),1.2*$M$21*$AH$77*$F$18/AT34,1.2*$M$21*$AH$77*$AN$9*$F$18/AT34^2)) -> #N/A | AW34: =MAX(AU34:AV34) -> #N/A | AZ34: =AZ33+0.05 -> 1.55 | BA34: =IF($F$16="NSR 10",AQ34,AW34) -> 0.49548387
AP35: =AP34+0.05 -> 1.6 | AQ35: =IF(AP35<$AM$3,2.5*$M$20*$M$23,IF(AND(AP35>=$AM$3,AP35<$AM$4),1.2*$M$21*$M$24/AP35,1.2*$M$21*$M$24*$AM$4/AP35^2)) -> 0.48 | AT35: =AT34+0.05 -> 1.6 | AU35: =IF(AT35<$AM$8,2.5*$M$20*$M$23*$F$18,IF(AND(AT35>=$AM$8,AT35<$AM$9),1.2*$M$21*$M$24*$F$18/AT35,1.2*$M$21*$M$24*$AM$9*$F$18/AT35^2)) -> #N/A | AV35: =IF(AT35<$AN$8,2.5*$M$20*$AH$76*$F$18,IF(AND(AT35>=$AN$8,AT35<$AN$9),1.2*$M$21*$AH$77*$F$18/AT35,1.2*$M$21*$AH$77*$AN$9*$F$18/AT35^2)) -> #N/A | AW35: =MAX(AU35:AV35) -> #N/A | AZ35: =AZ34+0.05 -> 1.6 | BA35: =IF($F$16="NSR 10",AQ35,AW35) -> 0.48
W36: ESPECTRO DE PERIODO LARGO | AP36: =AP35+0.05 -> 1.65 | AQ36: =IF(AP36<$AM$3,2.5*$M$20*$M$23,IF(AND(AP36>=$AM$3,AP36<$AM$4),1.2*$M$21*$M$24/AP36,1.2*$M$21*$M$24*$AM$4/AP36^2)) -> 0.46545455 | AT36: =AT35+0.05 -> 1.65 | AU36: =IF(AT36<$AM$8,2.5*$M$20*$M$23*$F$18,IF(AND(AT36>=$AM$8,AT36<$AM$9),1.2*$M$21*$M$24*$F$18/AT36,1.2*$M$21*$M$24*$AM$9*$F$18/AT36^2)) -> #N/A | AV36: =IF(AT36<$AN$8,2.5*$M$20*$AH$76*$F$18,IF(AND(AT36>=$AN$8,AT36<$AN$9),1.2*$M$21*$AH$77*$F$18/AT36,1.2*$M$21*$AH$77*$AN$9*$F$18/AT36^2)) -> #N/A | AW36: =MAX(AU36:AV36) -> #N/A | AZ36: =AZ35+0.05 -> 1.65 | BA36: =IF($F$16="NSR 10",AQ36,AW36) -> 0.46545455
W37: Microzona | Y37: Aa | Z37: 0.25 | AA37: Av | AB37: 0.25 | AP37: =AP36+0.05 -> 1.7 | AQ37: =IF(AP37<$AM$3,2.5*$M$20*$M$23,IF(AND(AP37>=$AM$3,AP37<$AM$4),1.2*$M$21*$M$24/AP37,1.2*$M$21*$M$24*$AM$4/AP37^2)) -> 0.45176471 | AT37: =AT36+0.05 -> 1.7 | AU37: =IF(AT37<$AM$8,2.5*$M$20*$M$23*$F$18,IF(AND(AT37>=$AM$8,AT37<$AM$9),1.2*$M$21*$M$24*$F$18/AT37,1.2*$M$21*$M$24*$AM$9*$F$18/AT37^2)) -> #N/A | AV37: =IF(AT37<$AN$8,2.5*$M$20*$AH$76*$F$18,IF(AND(AT37>=$AN$8,AT37<$AN$9),1.2*$M$21*$AH$77*$F$18/AT37,1.2*$M$21*$AH$77*$AN$9*$F$18/AT37^2)) -> #N/A | AW37: =MAX(AU37:AV37) -> #N/A | AZ37: =AZ36+0.05 -> 1.7 | BA37: =IF($F$16="NSR 10",AQ37,AW37) -> 0.45176471
Y38: Tc | Z38: Fa | AA38: TL | AB38: Fv | AP38: =AP37+0.05 -> 1.75 | AQ38: =IF(AP38<$AM$3,2.5*$M$20*$M$23,IF(AND(AP38>=$AM$3,AP38<$AM$4),1.2*$M$21*$M$24/AP38,1.2*$M$21*$M$24*$AM$4/AP38^2)) -> 0.43885714 | AT38: =AT37+0.05 -> 1.75 | AU38: =IF(AT38<$AM$8,2.5*$M$20*$M$23*$F$18,IF(AND(AT38>=$AM$8,AT38<$AM$9),1.2*$M$21*$M$24*$F$18/AT38,1.2*$M$21*$M$24*$AM$9*$F$18/AT38^2)) -> #N/A | AV38: =IF(AT38<$AN$8,2.5*$M$20*$AH$76*$F$18,IF(AND(AT38>=$AN$8,AT38<$AN$9),1.2*$M$21*$AH$77*$F$18/AT38,1.2*$M$21*$AH$77*$AN$9*$F$18/AT38^2)) -> #N/A | AW38: =MAX(AU38:AV38) -> #N/A | AZ38: =AZ37+0.05 -> 1.75 | BA38: =IF($F$16="NSR 10",AQ38,AW38) -> 0.43885714
W39: 1 | Y39: 0.55 | Z39: 0.86 | AA39: 3 | AB39: 0.99 | AP39: =AP38+0.05 -> 1.8 | AQ39: =IF(AP39<$AM$3,2.5*$M$20*$M$23,IF(AND(AP39>=$AM$3,AP39<$AM$4),1.2*$M$21*$M$24/AP39,1.2*$M$21*$M$24*$AM$4/AP39^2)) -> 0.42666667 | AT39: =AT38+0.05 -> 1.8 | AU39: =IF(AT39<$AM$8,2.5*$M$20*$M$23*$F$18,IF(AND(AT39>=$AM$8,AT39<$AM$9),1.2*$M$21*$M$24*$F$18/AT39,1.2*$M$21*$M$24*$AM$9*$F$18/AT39^2)) -> #N/A | AV39: =IF(AT39<$AN$8,2.5*$M$20*$AH$76*$F$18,IF(AND(AT39>=$AN$8,AT39<$AN$9),1.2*$M$21*$AH$77*$F$18/AT39,1.2*$M$21*$AH$77*$AN$9*$F$18/AT39^2)) -> #N/A | AW39: =MAX(AU39:AV39) -> #N/A | AZ39: =AZ38+0.05 -> 1.8 | BA39: =IF($F$16="NSR 10",AQ39,AW39) -> 0.42666667
W40: 2 | Y40: 0.45 | Z40: 1.2 | AA40: 3 | AB40: 1.13 | AP40: =AP39+0.05 -> 1.85 | AQ40: =IF(AP40<$AM$3,2.5*$M$20*$M$23,IF(AND(AP40>=$AM$3,AP40<$AM$4),1.2*$M$21*$M$24/AP40,1.2*$M$21*$M$24*$AM$4/AP40^2)) -> 0.41513514 | AT40: =AT39+0.05 -> 1.85 | AU40: =IF(AT40<$AM$8,2.5*$M$20*$M$23*$F$18,IF(AND(AT40>=$AM$8,AT40<$AM$9),1.2*$M$21*$M$24*$F$18/AT40,1.2*$M$21*$M$24*$AM$9*$F$18/AT40^2)) -> #N/A | AV40: =IF(AT40<$AN$8,2.5*$M$20*$AH$76*$F$18,IF(AND(AT40>=$AN$8,AT40<$AN$9),1.2*$M$21*$AH$77*$F$18/AT40,1.2*$M$21*$AH$77*$AN$9*$F$18/AT40^2)) -> #N/A | AW40: =MAX(AU40:AV40) -> #N/A | AZ40: =AZ39+0.05 -> 1.85 | BA40: =IF($F$16="NSR 10",AQ40,AW40) -> 0.41513514
...

Sheet 4. MASA (MODELO)
A1: ='0. CARTA RESPONSABILIDAD'!A1 -> Memoria de cálculos estructurales | F1: Proyecto: | H1: ='0. CARTA RESPONSABILIDAD'!H1 -> EDIFICACIÓN LOCALES COMERCIALES | O1: Fecha: | Q1: ='0. CARTA RESPONSABILIDAD'!Q1 -> Mayo de 2025
O2: Diseño: | Q2: ='0. CARTA RESPONSABILIDAD'!Q2
F3: Contiene: | H3: DISTRIBUCIÓN DE MASAS | O3: Revisión: | Q3: ='0. CARTA RESPONSABILIDAD'!Q3 -> R0
B5: 4. DISTRIBUCIÓN DE MASAS
W7: Story forces. D. Bottom
B8: Se presenta la distribución de masas (pesos propios de elementos y cargas sobreimpuestas) por cada piso de la edificación:
W9: # | X9: Story | Y9: P | Z9: P piso | AB9: Elevación
F10: Story o Nivel | K10: Masa | Y10: KN | Z10: KN | AB10: m
K11: KN | W11: 15 | Z11: 0 | AB11: =MID(X11,3,100)
F12: ="#"&W11 -> #15 | H12: =IF(X11="","",X11) | W12: =W11-1 -> 14 | Z12: 0 | AB12: =MID(X12,3,100)
F13: ="#"&W12 -> #14 | H13: =IF(X12="","",X12) | W13: =W12-1 -> 13 | Z13: 0 | AB13: =MID(X13,3,100)
F14: ="#"&W13 -> #13 | H14: =IF(X13="","",X13) | W14: =W13-1 -> 12 | Z14: 0 | AB14: =MID(X14,3,100)
F15: ="#"&W14 -> #12 | H15: =IF(X14="","",X14) | W15: =W14-1 -> 11 | Z15: 0 | AB15: =MID(X15,3,100)
F16: ="#"&W15 -> #11 | H16: =IF(X15="","",X15) | W16: =W15-1 -> 10 | Z16: 0 | AB16: =MID(X16,3,100)
F17: ="#"&W16 -> #10 | H17: =IF(X16="","",X16) | W17: =W16-1 -> 9 | Z17: 0 | AB17: =MID(X17,3,100)
F18: ="#"&W17 -> #9 | H18: =IF(X17="","",X17) | W18: =W17-1 -> 8 | Z18: 0 | AB18: =MID(X18,3,100)
F19: ="#"&W18 -> #8 | H19: =IF(X18="","",X18) | W19: =W18-1 -> 7 | Z19: 0 | AB19: =MID(X19,3,100)
F20: ="#"&W19 -> #7 | H20: =IF(X19="","",X19) | W20: =W19-1 -> 6 | Z20: 0
F21: ="#"&W20 -> #6 | H21: =IF(X20="","",X20) | W21: =W20-1 -> 5 | Z21: =Y21-Y20 -> 0
F22: ="#"&W21 -> #5 | H22: =IF(X21="","",X21) | W22: =W21-1 -> 4 | Z22: =Y22-Y21 -> 0
F23: ="#"&W22 -> #4 | H23: =IF(X22="","",X22) | W23: =W22-1 -> 3 | X23: N+08.10 | Y23: 3072.9181 | Z23: =Y23-Y22 -> 3072.9181 | AB23: 3.1
F24: ="#"&W23 -> #3 | H24: =IF(X23="","",X23) -> N+08.10 | K24: =IF(Z23="","",Z23) -> 3072.9181 | W24: =W23-1 -> 2 | X24: N+05.00 | Y24: 6818.6868 | Z24: =Y24-Y23 -> 3745.7687 | AB24: 5
F25: ="#"&W24 -> #2 | H25: =IF(X24="","",X24) -> N+05.00 | K25: =IF(Z24="","",Z24) -> 3745.7687 | W25: =W24-1 -> 1 | X25: N-0.00 | Y25: =Y24 -> 6818.6868 | Z25: =Y25-Y24 -> 0 | AB25: 0
F26: ="#"&W25 -> #1 | H26: =IF(X25="","",X25) -> N-0.00 | K26: =IF(Z25="","",Z25) -> 0
H27: TOTAL | K27: =SUM(K12:N26) -> 6818.6868

Sheet 5. IRREGULARIDADES
A1: ='0. CARTA RESPONSABILIDAD'!A1 -> Memoria de cálculos estructurales | F1: Proyecto: | H1: ='0. CARTA RESPONSABILIDAD'!H1 -> EDIFICACIÓN LOCALES COMERCIALES | O1: Fecha: | Q1: ='0. CARTA RESPONSABILIDAD'!Q1 -> Mayo de 2025
O2: Diseño: | Q2: ='0. CARTA RESPONSABILIDAD'!Q2
F3: Contiene: | H3: CHEQUEO IRREGULARIDAD Y COEF. R | O3: Revisión: | Q3: ='0. CARTA RESPONSABILIDAD'!Q3 -> R0
B5: 5. IRREGULARIDADES
B8: 3.1. IRREGULARIDADES EN PLANTA
B10: 3.1.1 Irregularidad torsional (1aP,1bP) | L10: 3.1.2 Retrocesos en las esquinas (2P)
B12: Nivel | C12: Δmax | E12: Δavg | G12: Δmax/Δavg | H12: φp | I12: Irregular | L12: A | M12: 0 | N12: m
B13: 3 | C13: 0.01 | E13: 0.01 | G13: =C13/E13 -> 1 | I13: =IF(AND(1.4>=G13,G13>1.2),0.9,IF(G13>1.4,0.8,1)) -> 1 | J13: =IF(I13=0.9,"1aP",IF(I13=0.8,"1bP","NO")) -> NO | L13: B | M13: 20.75 | N13: m
L14: C | M14: 0 | N14: m
L15: D | M15: 20.75 | N15: m
L17: A>0.15B | N17: =IF(M12>0.15*M13,"2P","OK") -> OK
L18: C>0.15D | N18: =IF(M14>0.15*M15,"2P","OK") -> OK
H19: φp | I19: =MIN(I13:I18) -> 1 | L19: φp | N19: =IF(OR(N17="2P",N18="2P"),0.9,1) -> 1
B30: 3.1.3 Irregularidad del diafragma (3P)
F32: A | G32: =+M13 -> 20.75 | H32: m | O32: A | P32: =+M13 -> 20.75 | Q32: m
F33: B | G33: =+M15 -> 20.75 | H33: m | O33: B | P33: =+M15 -> 20.75 | Q33: m
F34: C | G34: 0 | H34: m | O34: C | P34: 0 | Q34: m
F35: D | G35: 0 | H35: m | O35: D | P35: 0 | Q35: m
O36: E | P36: 0 | Q36: m
F38: CxD>0.5AxB | H38: =IF(G34*G35>0.5*G32*G33,"3P","OK") -> OK | O38: (CxD+CxE)>0.5AxB | R38: =IF(P34*P35+P34*P36>0.5*P32*P33,"3P","OK") -> OK
F39: φp | H39: =IF(H38="3P",0.9,1) -> 1 | O39: φp | R39: =IF(R38="3P",0.9,1) -> 1
B50: 3.1.4 Desplazamiento del plano de acción (4P) | M50: 3.1.5 Sistemas no paralelos (5P)
B52: ¿Aplica? | D52: NO | E52: φp | F52: =IF(D52="SÍ",0.8,1) -> 1 | M52: ¿Aplica? | O52: NO | P52: φp | Q52: =IF(O52="SÍ",0.8,1) -> 1
B67: 3.2. IRREGULARIDADES EN ALTURA
B69: 3.2.1 Piso flexible (1aA, 1bA) | G69: ¿Aplica? | I69: NO | M69: 3.2.2 Distribución de masa (2A) | R69: ¿Aplica? | T69: NO
B71: Piso i | C71: Rigidez i | D71: φa - flexible | F71: φa - extremo | M71: Piso i | N71: Masa i | O71: φa
D72: Ec. 1 | E72: Ec. 2 | F72: Ec. 3 | G72: Ec. 4 | N72: KN
B73: J | M73: J
B74: I | M74: I | O74: =IF(OR(N74>1.5*N73,N74>1.5*N75),0.9,1) -> 1
B75: H | M75: H | O75: =IF(OR(N75>1.5*N74,N75>1.5*N76),0.9,1) -> 1
B76: G | M76: G | O76: =IF(OR(N76>1.5*N75,N76>1.5*N77),0.9,1) -> 1
B77: F | M77: F | O77: =IF(OR(N77>1.5*N76,N77>1.5*N78),0.9,1) -> 1
B78: E | M78: E | O78: =IF(OR(N78>1.5*N77,N78>1.5*N79),0.9,1) -> 1
B79: D | M79: D | N79: ='4. MASA (MODELO)'!K23 -> 0 | O79: =IF(OR(N79>1.5*N78,N79>1.5*N80),0.9,1) -> 1
B80: C | M80: C | N80: ='4. MASA (MODELO)'!K24 -> 3072.9181 | O80: =IF(OR(N80>1.5*N79,N80>1.5*N81),0.9,1) -> 0.9
B81: B | M81: B | N81: ='4. MASA (MODELO)'!K25 -> 3745.7687 | O81: =IF(OR(N81>1.5*N80,N81>1.5*N82),0.9,1) -> 0.9
B82: A | M82: A | N82: ='4. MASA (MODELO)'!K26 -> 0
B84: φa | C84: =IF(I69="SÍ",MIN(D73:G82),1) -> 1 | M84: φa | N84: =IF(T69="NO",1,MIN(O73:O82)) -> 1
B86: Ec. 1 | C86: 0.6Ki+1<=Ki<0.7Ki+1
B87: Ec. 2 | C87: 0.7/3(Ki+1 + Ki+2 + Ki+3)<=Ki<0.8/3(Ki+1 + Ki+2 + Ki+3)
...

Sheet 6. PERIODOS Y MASA EXCITADA
A1: ='0. CARTA RESPONSABILIDAD'!A1 -> Memoria de cálculos estructurales | F1: Proyecto: | H1: ='0. CARTA RESPONSABILIDAD'!H1 -> EDIFICACIÓN LOCALES COMERCIALES | O1: Fecha: | Q1: ='0. CARTA RESPONSABILIDAD'!Q1 -> Mayo de 2025
O2: Diseño: | Q2: ='0. CARTA RESPONSABILIDAD'!Q2 | W2: Modal participation mass ratios
F3: Contiene: | H3: PERIODOS Y MASA EXCITADA | O3: Revisión: | Q3: ='0. CARTA RESPONSABILIDAD'!Q3 -> R0
B5: 6. PERIODOS Y MASA EXCITADA
B8: Se verifica que en ambas direcciones se pueda exitar más del 80% de la masa de la estructura. Se anexa el reporte de ETABS con los porcentajes de participación de masa en los modos de la estructura.
B11: Mode | D11: Period | F11: UX | H11: UY | J11: UZ | L11: Sum UX | N11: Sum UY | P11: Sum UZ | S11: Número de modos | W11: Case | X11: Mode | Y11: Period | Z11: UX | AA11: UY | AB11: UZ | AC11: SumUX | AD11: SumUY | AE11: SumUZ | AF11: RX | AG11: RY | AH11: RZ | AI11: SumRX | AJ11: SumRY | AK11: SumRZ
D12: sec | Y12: sec
B13: =X13 -> 1 | D13: =Y13 -> 0.429 | F13: =Z13 -> 1.377e-06 | H13: =AA13 -> 0.9205 | J13: =AB13 -> 2.555e-05 | L13: =AC13 -> 1.377e-06 | N13: =AD13 -> 0.9205 | P13: =AE13 -> 2.555e-05 | S13: =MAX(B13:C64) -> 52 | W13: Modal | X13: 1 | Y13: 0.429 | Z13: 1.377e-06 | AA13: 0.9205 | AB13: 2.555e-05 | AC13: 1.377e-06 | AD13: 0.9205 | AE13: 2.555e-05 | AF13: 0.0109 | AG13: 5.436e-07 | AH13: 0.0002 | AI13: 0.0109 | AJ13: 5.436e-07 | AK13: 0.0002
B14: =X14 -> 2 | D14: =Y14 -> 0.375 | F14: =Z14 -> 0.9292 | H14: =AA14 -> 4.286e-06 | J14: =AB14 -> 1.708e-05 | L14: =AC14 -> 0.9292 | N14: =AD14 -> 0.9205 | P14: =AE14 -> 4.263e-05 | W14: Modal | X14: 2 | Y14: 0.375 | Z14: 0.9292 | AA14: 4.286e-06 | AB14: 1.708e-05 | AC14: 0.9292 | AD14: 0.9205 | AE14: 4.263e-05 | AF14: 2.33e-06 | AG14: 0.0047 | AH14: 0.011 | AI14: 0.0109 | AJ14: 0.0047 | AK14: 0.0112
B15: =X15 -> 3 | D15: =Y15 -> 0.307 | F15: =Z15 -> 0.0102 | H15: =AA15 -> 0.0001 | J15: =AB15 -> 2.782e-06 | L15: =AC15 -> 0.9395 | N15: =AD15 -> 0.9207 | P15: =AE15 -> 4.541e-05 | S15: Sentido X | W15: Modal | X15: 3 | Y15: 0.307 | Z15: 0.0102 | AA15: 0.0001 | AB15: 2.782e-06 | AC15: 0.9395 | AD15: 0.9207 | AE15: 4.541e-05 | AF15: 2.423e-05 | AG15: 0.0001 | AH15: 0.9152 | AI15: 0.0109 | AJ15: 0.0048 | AK15: 0.9264
B16: =X16 -> 4 | D16: =Y16 -> 0.179 | F16: =Z16 -> 0.0002 | H16: =AA16 -> 0 | J16: =AB16 -> 0.0001 | L16: =AC16 -> 0.9396 | N16: =AD16 -> 0.9207 | P16: =AE16 -> 0.0002 | S16: Masa | W16: Modal | X16: 4 | Y16: 0.179 | Z16: 0.0002 | AA16: 0 | AB16: 0.0001 | AC16: 0.9396 | AD16: 0.9207 | AE16: 0.0002 | AF16: 0.0001 | AG16: 0.0218 | AH16: 2.176e-06 | AI16: 0.011 | AJ16: 0.0266 | AK16: 0.9264
B17: =X17 -> 5 | D17: =Y17 -> 0.16 | F17: =Z17 -> 0.0007 | H17: =AA17 -> 0 | J17: =AB17 -> 0.0019 | L17: =AC17 -> 0.9403 | N17: =AD17 -> 0.9207 | P17: =AE17 -> 0.0021 | S17: =MAX(L13:M64) -> 0.9443 | W17: Modal | X17: 5 | Y17: 0.16 | Z17: 0.0007 | AA17: 0 | AB17: 0.0019 | AC17: 0.9403 | AD17: 0.9207 | AE17: 0.0021 | AF17: 0.0007 | AG17: 0.1264 | AH17: 7.388e-06 | AI17: 0.0117 | AJ17: 0.153 | AK17: 0.9264
B18: =X18 -> 6 | D18: =Y18 -> 0.155 | F18: =Z18 -> 1.299e-05 | H18: =AA18 -> 0 | J18: =AB18 -> 0.0002 | L18: =AC18 -> 0.9403 | N18: =AD18 -> 0.9207 | P18: =AE18 -> 0.0023 | S18: =IF(S17>=0.9,"OK","N/C") -> OK | W18: Modal | X18: 6 | Y18: 0.155 | Z18: 1.299e-05 | AA18: 0 | AB18: 0.0002 | AC18: 0.9403 | AD18: 0.9207 | AE18: 0.0023 | AF18: 0.0003 | AG18: 0.0021 | AH18: 2.853e-05 | AI18: 0.012 | AJ18: 0.1551 | AK18: 0.9264
B19: =X19 -> 7 | D19: =Y19 -> 0.153 | F19: =Z19 -> 0 | H19: =AA19 -> 0 | J19: =AB19 -> 0.0991 | L19: =AC19 -> 0.9403 | N19: =AD19 -> 0.9207 | P19: =AE19 -> 0.1014 | S19: Periodo | W19: Modal | X19: 7 | Y19: 0.153 | Z19: 0 | AA19: 0 | AB19: 0.0991 | AC19: 0.9403 | AD19: 0.9207 | AE19: 0.1014 | AF19: 0.0021 | AG19: 0.0014 | AH19: 3.218e-06 | AI19: 0.0141 | AJ19: 0.1565 | AK19: 0.9264
B20: =X20 -> 8 | D20: =Y20 -> 0.147 | F20: =Z20 -> 6.987e-07 | H20: =AA20 -> 0 | J20: =AB20 -> 0.1745 | L20: =AC20 -> 0.9403 | N20: =AD20 -> 0.9207 | P20: =AE20 -> 0.2759 | S20: =D14 -> 0.375 | W20: Modal | X20: 8 | Y20: 0.147 | Z20: 6.987e-07 | AA20: 0 | AB20: 0.1745 | AC20: 0.9403 | AD20: 0.9207 | AE20: 0.2759 | AF20: 0.0001 | AG20: 0.0001 | AH20: 2.144e-05 | AI20: 0.0143 | AJ20: 0.1566 | AK20: 0.9265
B21: =X21 -> 9 | D21: =Y21 -> 0.141 | F21: =Z21 -> 2.368e-06 | H21: =AA21 -> 0 | J21: =AB21 -> 0.0091 | L21: =AC21 -> 0.9403 | N21: =AD21 -> 0.9207 | P21: =AE21 -> 0.2851 | W21: Modal | X21: 9 | Y21: 0.141 | Z21: 2.368e-06 | AA21: 0 | AB21: 0.0091 | AC21: 0.9403 | AD21: 0.9207 | AE21: 0.2851 | AF21: 0.0119 | AG21: 0.0002 | AH21: 0.0001 | AI21: 0.0261 | AJ21: 0.1568 | AK21: 0.9265
B22: =X22 -> 10 | D22: =Y22 -> 0.139 | F22: =Z22 -> 0 | H22: =AA22 -> 0 | J22: =AB22 -> 0.0003 | L22: =AC22 -> 0.9403 | N22: =AD22 -> 0.9207 | P22: =AE22 -> 0.2853 | S22: Sentido Y | W22: Modal | X22: 10 | Y22: 0.139 | Z22: 0 | AA22: 0 | AB22: 0.0003 | AC22: 0.9403 | AD22: 0.9207 | AE22: 0.2853 | AF22: 0.0884 | AG22: 1.961e-06 | AH22: 0 | AI22: 0.1146 | AJ22: 0.1568 | AK22: 0.9265
B23: =X23 -> 11 | D23: =Y23 -> 0.131 | F23: =Z23 -> 9.3e-07 | H23: =AA23 -> 1.954e-06 | J23: =AB23 -> 0.0017 | L23: =AC23 -> 0.9403 | N23: =AD23 -> 0.9207 | P23: =AE23 -> 0.287 | S23: Masa | W23: Modal | X23: 11 | Y23: 0.131 | Z23: 9.3e-07 | AA23: 1.954e-06 | AB23: 0.0017 | AC23: 0.9403 | AD23: 0.9207 | AE23: 0.287 | AF23: 0.0558 | AG23: 3.018e-06 | AH23: 6.123e-07 | AI23: 0.1704 | AJ23: 0.1568 | AK23: 0.9265
B24: =X24 -> 12 | D24: =Y24 -> 0.126 | F24: =Z24 -> 6.303e-06 | H24: =AA24 -> 0 | J24: =AB24 -> 1.202e-05 | L24: =AC24 -> 0.9403 | N24: =AD24 -> 0.9207 | P24: =AE24 -> 0.287 | S24: =MAX(N13:O64) -> 0.9207 | W24: Modal | X24: 12 | Y24: 0.126 | Z24: 6.303e-06 | AA24: 0 | AB24: 1.202e-05 | AC24: 0.9403 | AD24: 0.9207 | AE24: 0.287 | AF24: 1.385e-05 | AG24: 0.0042 | AH24: 0 | AI24: 0.1704 | AJ24: 0.161 | AK24: 0.9265
B25: =X25 -> 13 | D25: =Y25 -> 0.126 | F25: =Z25 -> 0.0024 | H25: =AA25 -> 0 | J25: =AB25 -> 2.25e-06 | L25: =AC25 -> 0.9427 | N25: =AD25 -> 0.9207 | P25: =AE25 -> 0.287 | S25: =IF(S24>=0.9,"OK","N/C") -> OK | W25: Modal | X25: 13 | Y25: 0.126 | Z25: 0.0024 | AA25: 0 | AB25: 2.25e-06 | AC25: 0.9427 | AD25: 0.9207 | AE25: 0.287 | AF25: 8.408e-07 | AG25: 0.0085 | AH25: 6.096e-06 | AI25: 0.1704 | AJ25: 0.1695 | AK25: 0.9265
B26: =X26 -> 14 | D26: =Y26 -> 0.125 | F26: =Z26 -> 0 | H26: =AA26 -> 0 | J26: =AB26 -> 0.0099 | L26: =AC26 -> 0.9427 | N26: =AD26 -> 0.9207 | P26: =AE26 -> 0.297 | S26: Periodo | W26: Modal | X26: 14 | Y26: 0.125 | Z26: 0 | AA26: 0 | AB26: 0.0099 | AC26: 0.9427 | AD26: 0.9207 | AE26: 0.297 | AF26: 4.71e-05 | AG26: 3.245e-05 | AH26: 0 | AI26: 0.1705 | AJ26: 0.1696 | AK26: 0.9265
B27: =X27 -> 15 | D27: =Y27 -> 0.125 | F27: =Z27 -> 1.572e-06 | H27: =AA27 -> 0 | J27: =AB27 -> 0.0012 | L27: =AC27 -> 0.9427 | N27: =AD27 -> 0.9207 | P27: =AE27 -> 0.2982 | S27: =D13 -> 0.429 | W27: Modal | X27: 15 | Y27: 0.125 | Z27: 1.572e-06 | AA27: 0 | AB27: 0.0012 | AC27: 0.9427 | AD27: 0.9207 | AE27: 0.2982 | AF27: 4.911e-05 | AG27: 0.0032 | AH27: 6.404e-07 | AI27: 0.1705 | AJ27: 0.1728 | AK27: 0.9265
B28: =X28 -> 16 | D28: =Y28 -> 0.124 | F28: =Z28 -> 0.0001 | H28: =AA28 -> 0 | J28: =AB28 -> 8.017e-06 | L28: =AC28 -> 0.9429 | N28: =AD28 -> 0.9207 | P28: =AE28 -> 0.2982 | W28: Modal | X28: 16 | Y28: 0.124 | Z28: 0.0001 | AA28: 0 | AB28: 8.017e-06 | AC28: 0.9429 | AD28: 0.9207 | AE28: 0.2982 | AF28: 0 | AG28: 0.0008 | AH28: 9.214e-06 | AI28: 0.1705 | AJ28: 0.1735 | AK28: 0.9265
B29: =X29 -> 17 | D29: =Y29 -> 0.124 | F29: =Z29 -> 0.0012 | H29: =AA29 -> 0 | J29: =AB29 -> 1.175e-05 | L29: =AC29 -> 0.944 | N29: =AD29 -> 0.9207 | P29: =AE29 -> 0.2982 | W29: Modal | X29: 17 | Y29: 0.124 | Z29: 0.0012 | AA29: 0 | AB29: 1.175e-05 | AC29: 0.944 | AD29: 0.9207 | AE29: 0.2982 | AF29: 0 | AG29: 0.0075 | AH29: 8.787e-06 | AI29: 0.1705 | AJ29: 0.181 | AK29: 0.9265
B30: =X30 -> 18 | D30: =Y30 -> 0.124 | F30: =Z30 -> 0 | H30: =AA30 -> 0 | J30: =AB30 -> 4.225e-05 | L30: =AC30 -> 0.944 | N30: =AD30 -> 0.9207 | P30: =AE30 -> 0.2982 | W30: Modal | X30: 18 | Y30: 0.124 | Z30: 0 | AA30: 0 | AB30: 4.225e-05 | AC30: 0.944 | AD30: 0.9207 | AE30: 0.2982 | AF30: 2.077e-05 | AG30: 7.811e-07 | AH30: 0 | AI30: 0.1705 | AJ30: 0.181 | AK30: 0.9265
B31: =X31 -> 19 | D31: =Y31 -> 0.124 | F31: =Z31 -> 0 | H31: =AA31 -> 0 | J31: =AB31 -> 2.378e-05 | L31: =AC31 -> 0.944 | N31: =AD31 -> 0.9207 | P31: =AE31 -> 0.2983 | W31: Modal | X31: 19 | Y31: 0.124 | Z31: 0 | AA31: 0 | AB31: 2.378e-05 | AC31: 0.944 | AD31: 0.9207 | AE31: 0.2983 | AF31: 6.804e-07 | AG31: 6.186e-07 | AH31: 0 | AI31: 0.1705 | AJ31: 0.181 | AK31: 0.9265
B32: =X32 -> 20 | D32: =Y32 -> 0.124 | F32: =Z32 -> 6.122e-07 | H32: =AA32 -> 0 | J32: =AB32 -> 0.0001 | L32: =AC32 -> 0.944 | N32: =AD32 -> 0.9207 | P32: =AE32 -> 0.2983 | W32: Modal | X32: 20 | Y32: 0.124 | Z32: 6.122e-07 | AA32: 0 | AB32: 0.0001 | AC32: 0.944 | AD32: 0.9207 | AE32: 0.2983 | AF32: 0 | AG32: 1.72e-06 | AH32: 0 | AI32: 0.1705 | AJ32: 0.181 | AK32: 0.9265
B33: =X33 -> 21 | D33: =Y33 -> 0.124 | F33: =Z33 -> 1.386e-06 | H33: =AA33 -> 0 | J33: =AB33 -> 0.0001 | L33: =AC33 -> 0.944 | N33: =AD33 -> 0.9207 | P33: =AE33 -> 0.2985 | W33: Modal | X33: 21 | Y33: 0.124 | Z33: 1.386e-06 | AA33: 0 | AB33: 0.0001 | AC33: 0.944 | AD33: 0.9207 | AE33: 0.2985 | AF33: 1.137e-05 | AG33: 5.769e-06 | AH33: 1.211e-06 | AI33: 0.1705 | AJ33: 0.181 | AK33: 0.9265
B34: =X34 -> 22 | D34: =Y34 -> 0.124 | F34: =Z34 -> 8.329e-06 | H34: =AA34 -> 0 | J34: =AB34 -> 0.0002 | L34: =AC34 -> 0.9441 | N34: =AD34 -> 0.9207 | P34: =AE34 -> 0.2986 | W34: Modal | X34: 22 | Y34: 0.124 | Z34: 8.329e-06 | AA34: 0 | AB34: 0.0002 | AC34: 0.9441 | AD34: 0.9207 | AE34: 0.2986 | AF34: 0 | AG34: 1.371e-05 | AH34: 0 | AI34: 0.1705 | AJ34: 0.1811 | AK34: 0.9265
B35: =X35 -> 23 | D35: =Y35 -> 0.124 | F35: =Z35 -> 2.079e-05 | H35: =AA35 -> 0 | J35: =AB35 -> 0.0002 | L35: =AC35 -> 0.9441 | N35: =AD35 -> 0.9207 | P35: =AE35 -> 0.2989 | W35: Modal | X35: 23 | Y35: 0.124 | Z35: 2.079e-05 | AA35: 0 | AB35: 0.0002 | AC35: 0.9441 | AD35: 0.9207 | AE35: 0.2989 | AF35: 0.0001 | AG35: 4.519e-05 | AH35: 1.515e-06 | AI35: 0.1706 | AJ35: 0.1811 | AK35: 0.9265
B36: =X36 -> 24 | D36: =Y36 -> 0.123 | F36: =Z36 -> 0 | H36: =AA36 -> 0 | J36: =AB36 -> 4.32e-05 | L36: =AC36 -> 0.9441 | N36: =AD36 -> 0.9207 | P36: =AE36 -> 0.2989 | W36: Modal | X36: 24 | Y36: 0.123 | Z36: 0 | AA36: 0 | AB36: 4.32e-05 | AC36: 0.9441 | AD36: 0.9207 | AE36: 0.2989 | AF36: 0.0001 | AG36: 6.353e-07 | AH36: 0.0007 | AI36: 0.1707 | AJ36: 0.1811 | AK36: 0.9272
B37: =X37 -> 25 | D37: =Y37 -> 0.123 | F37: =Z37 -> 7.021e-07 | H37: =AA37 -> 0 | J37: =AB37 -> 0.0001 | L37: =AC37 -> 0.9441 | N37: =AD37 -> 0.9207 | P37: =AE37 -> 0.299 | W37: Modal | X37: 25 | Y37: 0.123 | Z37: 7.021e-07 | AA37: 0 | AB37: 0.0001 | AC37: 0.9441 | AD37: 0.9207 | AE37: 0.299 | AF37: 0.0001 | AG37: 0 | AH37: 3.544e-06 | AI37: 0.1707 | AJ37: 0.1811 | AK37: 0.9272
B38: =X38 -> 26 | D38: =Y38 -> 0.123 | F38: =Z38 -> 0 | H38: =AA38 -> 0 | J38: =AB38 -> 7.036e-06 | L38: =AC38 -> 0.9441 | N38: =AD38 -> 0.9207 | P38: =AE38 -> 0.299 | W38: Modal | X38: 26 | Y38: 0.123 | Z38: 0 | AA38: 0 | AB38: 7.036e-06 | AC38: 0.9441 | AD38: 0.9207 | AE38: 0.299 | AF38: 2.464e-05 | AG38: 0 | AH38: 4.718e-06 | AI38: 0.1708 | AJ38: 0.1811 | AK38: 0.9272
B39: =X39 -> 27 | D39: =Y39 -> 0.123 | F39: =Z39 -> 0 | H39: =AA39 -> 0 | J39: =AB39 -> 0.0001 | L39: =AC39 -> 0.9441 | N39: =AD39 -> 0.9207 | P39: =AE39 -> 0.2991 | W39: Modal | X39: 27 | Y39: 0.123 | Z39: 0 | AA39: 0 | AB39: 0.0001 | AC39: 0.9441 | AD39: 0.9207 | AE39: 0.2991 | AF39: 0 | AG39: 0 | AH39: 0 | AI39: 0.1708 | AJ39: 0.1811 | AK39: 0.9272
... B64: =X64 -> 52 | D64: =Y64 -> 0.122 | F64: =Z64 -> 3.266e-05 | H64: =AA64 -> 0 | J64: =AB64 -> 5.434e-06 | L64: =AC64 -> 0.9443 | N64: =AD64 -> 0.9207 | P64: =AE64 -> 0.3194 | W64: Modal | X64: 52 | Y64: 0.122 | Z64: 3.266e-05 | AA64: 0 | AB64: 5.434e-06 | AC64: 0.9443 | AD64: 0.9207 | AE64: 0.3194 | AF64: 0.0001 | AG64: 0.0001 | AH64: 3.56e-05 | AI64: 0.1794 | AJ64: 0.1917 | AK64: 0.9277
